Workbook
Name _E1: #REF!
Name _F1: #REF!
Name ddd: {"Book1"}
Name dfsfad: #REF!
Name Document_array: {"Book1"}
Name dusrmq: #REF!
Name 강남욱: {"Book1","2008년 9월활동보조 판정표.xls"}
Name 고: #REF!
Name 고등: #REF!
Name 고등고: #REF!
Name 공동주택거주학생비율: #REF!
Name 교: #REF!
Name 교사정원07: #REF!
Name 구분: #REF!
Name 그룹명: #REF!
Name 급별: #REF!
Name 대상자수: #REF!
Name ㅁ1: #REF!
Name ㅁㅁ: #REF!
Name 면적: #REF!
Name 목록: #REF!
Name 문서명: #REF!
Name 문서번호: #REF!
Name 미착수: #REF!
Name 발생지수: #REF!
Name 보유교실: #REF!
Name 보유교실1: #REF!
Name 보정값: #REF!
Name 비율: #REF!
Name 사람수: #REF!
Name 성별: #REF!
Name 수용지표: #REF!
Name 식료품: #REF!
Name 신설기준: #REF!
Name 신설비: #REF!
Name 아파트: #REF!
Name 아파트명: #REF!
Name 연급ㅂ: #REF!
Name 연차: #REF!
Name 용지비: #REF!
Name 용지비비: #REF!
Name 유발률: #REF!
Name 유형별: #REF!
Name 읍면동: #REF!
Name 의무취학: #REF!
Name 의무취학상황: #REF!
Name 의무취학자1세: #REF!
Name 의무취학자2세: #REF!
Name 의무취학자3세: #REF!
Name 의무취학자4세: #REF!
Name 의무취학자5세: #REF!
Name 의무취학학교명: #REF!
Name 이름: {"Book1"}
Name 이사분기: #REF!
Name 인구이동률: #REF!
Name 일사분가: #REF!
Name 일사분기: #REF!
Name 전체: #REF!
Name 주택수: #REF!
Name 주택종류: #REF!

Sheet DNI_WIRED_MEANSURE_AVG
A1: 학교코드 | B1: 학교명 | C1: 장비개수 | D1: Avg Throughput (Mbps) | E1: Avg Loss Ratio | F1: Avg Latency (ms) | G1: Avg Jitter (ns) | H1: 진단결과
A2: G107451009MS | B2: 가수원중학교 | C2: 12 | D2: 827.6833 | E2: 0.1125 | F2: 0.46 | G2: 24.8083 | H2: 양호
A3: G107451057ES | B3: 가수원초등학교 | C3: 17 | D3: 978.1471 | E3: 0.1859 | F3: 2.6506 | G3: 25.6471 | H3: 양호
A4: G107451010MS | B4: 갈마중학교 | C4: 20 | D4: 974.17 | E4: 0.2585 | F4: 14.261 | G4: 70.445 | H4: 양호
A5: G107430324HS | B5: 계룡디지텍고등학교 | C5: 16 | D5: 817.825 | E5: 0.0256 | F5: 1.3438 | G5: 11.1625 | H5: 양호
A6: G107451058ES | B6: 구즉초등학교 | C6: 21 | D6: 931.0571 | E6: 0.0652 | F6: 1.0381 | G6: 12.8952 | H6: 양호
A7: G107451059ES | B7: 금성초등학교 | C7: 23 | D7: 981.6957 | E7: 0.013 | F7: 1.2826 | G7: 23.4887 | H7: 양호
A8: G107451011MS | B8: 기성중학교 | C8: 12 | D8: 756.675 | E8: 0.1167 | F8: 1.9583 | G8: 38.5833 | H8: 양호
A9: G107451060ES | B9: 기성초등학교 | C9: 14 | D9: 915.2786 | E9: 0.06 | F9: 6.2286 | G9: 14.0071 | H9: 양호
A10: G107451061ES | B10: 기성초등학교길헌분교장 | C10: 9 | D10: 878.1778 | E10: 0.0156 | F10: 0.1111 | G10: 13.1889 | H10: 양호
A11: G107430046HS | B11: 남대전고등학교 | C11: 31 | D11: 981.9548 | E11: 0.1555 | F11: 5.2452 | G11: 21.6645 | H11: 양호
A12: G107451062ES | B12: 남선초등학교 | C12: 9 | D12: 777.2222 | E12: 0.2444 | F12: 4.9689 | G12: 186.8778 | H12: 양호
A13: G107430030HS | B13: 대덕고등학교 | C13: 49 | D13: 979.1531 | E13: 0.4188 | F13: 3.3702 | G13: 767.6245 | H13: 양호
... A316: G107451126ES | B316: 흥도초등학교 | C316: 21 | D316: 851.9476 | E316: 0.1533 | F316: 1.5743 | G316: 1869.9857 | H316: 양호

Sheet ISP측정_학교별평균
A1: 학교명 | B1: 학교코드 | C1: 다운로드 | D1: 업로드 | E1: RTT | F1: RSSI | G1: CH | H1: 다운로드 진단 | I1: 업로드 진단

Sheet 전부하측정_학교별평균
A1: 학교코드 | B1: 학교명 | C1: 다운로드 | D1: 업로드 | E1: *RSSI | F1: CH | G1: 다운로드 진단 | H1: 업로드 진단

Sheet 집선ISP
A1: 학교코드 | B1: 학교명 | C1: 다운로드 | D1: 업로드 | E1: 지연
A2: =_xlfn.XLOOKUP(B2,Sheet1!C:C,Sheet1!A:A," ",0) -> G107451057ES | B2: 가수원초등학교 | C2: 2736 | D2: 8084.18 | E2: 4.03 | F2: 2.5G
A3: =_xlfn.XLOOKUP(B3,Sheet1!C:C,Sheet1!A:A," ",0) -> G107451010MS | B3: 갈마중학교 | C3: 994.88 | D3: 981.23 | E3: 1.68 | F3: 1G
A4: =_xlfn.XLOOKUP(B4,Sheet1!C:C,Sheet1!A:A," ",0) -> G107451058ES | B4: 구즉초등학교 | C4: 2533.1 | D4: 2458.4 | E4: 6.09 | F4: 2.5G
A5: =_xlfn.XLOOKUP(B5,Sheet1!C:C,Sheet1!A:A," ",0) -> G107451059ES | B5: 금성초등학교 | C5: 2724.55 | D5: 2720.89 | E5: 4.23 | F5: 2.5G
A6: =_xlfn.XLOOKUP(B6,Sheet1!C:C,Sheet1!A:A," ",0) -> G107451011MS | B6: 기성중학교 | C6: 976.35 | D6: 951.28 | E6: 2.81 | F6: 1G
A7: =_xlfn.XLOOKUP(B7,Sheet1!C:C,Sheet1!A:A," ",0) -> G107451060ES | B7: 기성초등학교 | C7: 982.96 | D7: 978.24 | E7: 1.96 | F7: 1G
A8: =_xlfn.XLOOKUP(B8,Sheet1!C:C,Sheet1!A:A," ",0) -> G107451061ES | B8: 기성초등학교길헌분교장 | C8: 832.42 | D8: 872.66 | E8: 6.31 | F8: 1G
A9: =_xlfn.XLOOKUP(B9,Sheet1!C:C,Sheet1!A:A," ",0) -> G107430046HS | B9: 남대전고등학교 | C9: 2083.6 | D9: 2300.8 | E9: 4.9 | F9: 2.5G
A10: =_xlfn.XLOOKUP(B10,Sheet1!C:C,Sheet1!A:A," ",0) -> G107451062ES | B10: 남선초등학교 | C10: 964.87 | D10: 926.01 | E10: 6.31 | F10: 1G
A11: =_xlfn.XLOOKUP(B11,Sheet1!C:C,Sheet1!A:A," ",0) -> G107430310HS | B11: 대덕소프트웨어마이스터고등학교 | C11: 982.75 | D11: 839.14 | E11: 6.09 | F11: 1G
A12: =_xlfn.XLOOKUP(B12,Sheet1!C:C,Sheet1!A:A," ",0) -> G107451012MS | B12: 대덕중학교 | C12: 993.48 | D12: 973.4 | E12: 2.69 | F12: 1G
A13: =_xlfn.XLOOKUP(B13,Sheet1!C:C,Sheet1!A:A," ",0) -> G107451063ES | B13: 대덕초등학교 | C13: 2551.15 | D13: 2656.19 | E13: 3.99 | F13: 2.5G
... A301: =_xlfn.XLOOKUP(B301,Sheet1!C:C,Sheet1!A:A," ",0) -> G107441047MS | B301: 회덕중학교 | C301: 960.4 | D301: 879.73 | E301: 5.06 | F301: 1G

Sheet 학교별통신장비현황
F1: 학교수 | G1: =COUNTIF(G5:G319, "*M")+COUNTIF(G5:G319, "*G")+COUNTIF(G5:G319, "*공유") -> 312 | H1: =COUNTIF(H5:H319, "2.5G*") -> 148 | I1: =COUNTIF(I5:I319, "확*") + COUNTIF(I5:I319, "미*") -> 0 | J1: =SUBTOTAL(102,J$5:J$319) -> 315 | K1: =COUNTIF(K5:K319, ">=1") -> 277 | L1: =COUNTIF(L5:L319, ">=1") -> 269 | M1: =COUNTIF(M5:M319, ">=1") -> 314 | N1: =COUNTIF(N5:N319, ">=1") -> 313 | O1: =COUNTIF(O5:O319, ">=1") -> 51 | Q1: =COUNTIF(Q5:Q319, ">=1") -> 252 | R1: =COUNTIF(R5:R319, ">=1") -> 180 | S1: =COUNTIF(S5:S319, ">=1") -> 2 | T1: =COUNTIF(T5:T319, ">=1") -> 110 | U1: =COUNTIF(U5:U319, ">=1") -> 88 | V1: =COUNTIF(V5:V319, ">=1") -> 7 | W1: =COUNTIF(W5:W319, ">=1") -> 77 | X1: =COUNTIF(X5:X319, ">=1") -> 55 | ... AS1: =COUNTIF(AS5:AS319, ">=1") -> 0
F2: 합계 | G2: =SUBTOTAL(103,G$5:G$319) -> 312 | H2: =SUBTOTAL(103,H$5:H$319) -> 155 | I2: =SUBTOTAL(103,I$5:I$319) -> 315 | J2: =SUBTOTAL(109,J$5:J$319) -> 626 | K2: =SUBTOTAL(109,K$5:K$319) -> 443 | L2: =SUBTOTAL(109,L$5:L$319) -> 313 | M2: =SUBTOTAL(109,M$5:M$319) -> 2996 | N2: =SUBTOTAL(109,N$5:N$319) -> 1172 | O2: =SUBTOTAL(109,O$5:O$319) -> 65 | Q2: =SUBTOTAL(109,Q$5:Q$319) -> 1084 | R2: =SUBTOTAL(109,R$5:R$319) -> 464 | S2: =SUBTOTAL(109,S$5:S$319) -> 3 | T2: =SUBTOTAL(109,T$5:T$319) -> 257 | U2: =SUBTOTAL(109,U$5:U$319) -> 132 | V2: =SUBTOTAL(109,V$5:V$319) -> 26 | W2: =SUBTOTAL(109,W$5:W$319) -> 163 | X2: =SUBTOTAL(109,X$5:X$319) -> 96 | ... AS2: =SUBTOTAL(109,AS$5:AS$319) -> 0
B3: =COUNTIF(B5:B319,"Y") -> 315 | J3: 방화벽 | K3: 보안L2/L3 | M3: L2SW | Q3: L2SW(100M) | T3: 광케이블MM | W3: 광케이블SM | Z3: Cat6 | AC3: Cat5E | AF3: Cat5 | AI3: L2SW(10G) | AJ3: L2PoE(2.5G이상) | AK3: L2PoE(1G이상) | AL3: 기타L2/L3 | AM3: 무선AP5이하 | AN3: 무선AP6이상 | AO3: 광케이블MM_무선 | AP3: 광케이블SM_무선 | AQ3: Cat6_무선 | AR3: Cat5E _무선 | AS3: Cat5 _무선
A4: 학교코드 | B4: 진단대상 | C4: 교육청 | D4: 지역 | E4: 학교유형 | F4: 학교명 | G4: 스쿨넷 회선속도 | H4: 무선망 전용 회선속도 | I4: 망분리현황 | J4: 스쿨넷 | K4: 업무망 | L4: 교육망 | M4: 업무망 | N4: 교육망 | O4: 기타 | P4: 합계 | Q4: 업무망 | R4: 교육망 | S4: 기타 | T4: 업무망 | U4: 교육망 | V4: 기타 | W4: 업무망 | X4: 교육망 | Y4: 기타 | Z4: 업무망 | AA4: 교육망 | AB4: 기타 | AC4: 업무망 | AD4: 교육망 | AE4: 기타 | AF4: 업무망 | AG4: 교육망 | AH4: 기타 | AI4: 무선망 | AJ4: 무선망 | AK4: 무선망 | AL4: 무선망 | AM4: 무선망 | AN4: 무선망 | AO4: 무선망 | AP4: 무선망 | AQ4: 무선망 | AR4: 무선망 | AS4: 무선망 | AU4: 계위 단계수
A5: G107441266MS | B5: Y | C5: 대전 | D5: 대덕구 | E5: 중학교 | F5: 대전경덕중학교 | G5: 1G | I5: O | J5: 2 | K5: 0 | L5: 0 | M5: 10 | N5: 3 | O5: 1 | P5: 0 | Q5: 0 | R5: 0 | S5: 0 | T5: 2 | U5: 1 | V5: 0 | W5: 0 | X5: 0 | Y5: 0 | Z5: 4 | AA5: 1 | AB5: 5 | AC5: 0 | AD5: 0 | AE5: 0 | AF5: 0 | AG5: 0 | AH5: 0 | AI5: 1 | AJ5: 0 | AK5: 6 | AL5: 1 | AM5: 0 | AN5: 23 | AO5: 2 | AP5: 5 | AQ5: 24
A6: G107441056ES | B6: Y | C6: 대전 | D6: 대덕구 | E6: 초등학교 | F6: 대전대양초등학교 | G6: 1G | I6: O | J6: 2 | K6: 1 | L6: 1 | M6: 15 | N6: 1 | O6: 0 | P6: 3 | Q6: 1 | R6: 2 | S6: 0 | T6: 0 | U6: 0 | V6: 0 | W6: 0 | X6: 0 | Y6: 0 | Z6: 0 | AA6: 0 | AB6: 0 | AC6: 0 | AD6: 0 | AE6: 0 | AF6: 15 | AG6: 2 | AH6: 0 | AI6: 1 | AJ6: 1 | AK6: 4 | AL6: 0 | AM6: 18 | AN6: 32 | AO6: 0 | AP6: 4 | AQ6: 51
A7: G107441016MS | B7: Y | C7: 대전 | D7: 대덕구 | E7: 중학교 | F7: 대전대청중학교 | G7: 1G | I7: X | J7: 2 | K7: 1 | L7: 2 | M7: 21 | N7: 5 | O7: 0 | P7: 2 | Q7: 1 | R7: 1 | S7: 0 | T7: 2 | U7: 1 | V7: 0 | W7: 0 | X7: 0 | Y7: 0 | Z7: 20 | AA7: 4 | AB7: 0 | AC7: 0 | AD7: 0 | AE7: 0 | AF7: 0 | AG7: 0 | AH7: 0 | AI7: 1 | AJ7: 0 | AK7: 7 | AL7: 0 | AM7: 1 | AN7: 32 | AO7: 1 | AP7: 3 | AQ7: 33
A8: G107441017MS | B8: Y | C8: 대전 | D8: 대덕구 | E8: 중학교 | F8: 대전대화중학교 | G8: 1G | I8: X | J8: 2 | K8: 1 | L8: 1 | M8: 11 | N8: 2 | O8: 0 | P8: 4 | Q8: 3 | R8: 1 | S8: 0 | T8: 0 | U8: 0 | V8: 0 | W8: 0 | X8: 0 | Y8: 0 | Z8: 0 | AA8: 0 | AB8: 0 | AC8: 13 | AD8: 2 | AE8: 0 | AF8: 0 | AG8: 0 | AH8: 0 | AI8: 1 | AJ8: 0 | AK8: 5 | AL8: 0 | AM8: 0 | AN8: 24 | AO8: 0 | AP8: 4 | AQ8: 25
A9: G107441057ES | B9: Y | C9: 대전 | D9: 대덕구 | E9: 초등학교 | F9: 대전대화초등학교 | G9: 1G | I9: O | J9: 2 | K9: 3 | L9: 1 | M9: 6 | N9: 2 | O9: 0 | P9: 6 | Q9: 4 | R9: 2 | S9: 0 | T9: 0 | U9: 0 | V9: 0 | W9: 1 | X9: 1 | Y9: 0 | Z9: 8 | AA9: 2 | AB9: 0 | AC9: 0 | AD9: 0 | AE9: 0 | AF9: 0 | AG9: 0 | AH9: 0 | AI9: 1 | AJ9: 1 | AK9: 3 | AL9: 0 | AM9: 14 | AN9: 11 | AO9: 0 | AP9: 2 | AQ9: 27
A10: G107441060ES | B10: Y | C10: 대전 | D10: 대덕구 | E10: 초등학교 | F10: 대전동도초등학교 | G10: 1G | I10: X | J10: 2 | K10: 3 | L10: 1 | M10: 7 | N10: 4 | O10: 0 | P10: 8 | Q10: 8 | R10: 0 | S10: 0 | T10: 1 | U10: 1 | V10: 0 | W10: 0 | X10: 0 | Y10: 0 | Z10: 0 | AA10: 0 | AB10: 0 | AC10: 13 | AD10: 2 | AE10: 0 | AF10: 0 | AG10: 0 | AH10: 0 | AI10: 1 | AJ10: 1 | AK10: 3 | AL10: 0 | AM10: 11 | AN10: 8 | AO10: 1 | AP10: 2 | AQ10: 20
A11: G107441062ES | B11: Y | C11: 대전 | D11: 대덕구 | E11: 초등학교 | F11: 대전동산초등학교 | G11: 1G | I11: O | J11: 2 | K11: 1 | L11: 2 | M11: 7 | N11: 1 | O11: 0 | P11: 5 | Q11: 3 | R11: 2 | S11: 0 | T11: 0 | U11: 0 | V11: 0 | W11: 0 | X11: 0 | Y11: 0 | Z11: 0 | AA11: 0 | AB11: 0 | AC11: 9 | AD11: 2 | AE11: 0 | AF11: 0 | AG11: 0 | AH11: 0 | AI11: 1 | AJ11: 1 | AK11: 6 | AL11: 0 | AM11: 12 | AN11: 35 | AO11: 0 | AP11: 5 | AQ11: 49
A12: G107441019MS | B12: Y | C12: 대전 | D12: 대덕구 | E12: 중학교 | F12: 대전매봉중학교 | G12: 1G | H12: 2.5G | I12: X | J12: 2 | K12: 2 | L12: 1 | M12: 9 | N12: 4 | O12: 0 | P12: 3 | Q12: 3 | R12: 0 | S12: 0 | T12: 0 | U12: 1 | V12: 0 | W12: 0 | X12: 0 | Y12: 0 | Z12: 11 | AA12: 2 | AB12: 0 | AC12: 0 | AD12: 0 | AE12: 0 | AF12: 0 | AG12: 0 | AH12: 0 | AI12: 1 | AJ12: 0 | AK12: 6 | AL12: 0 | AM12: 0 | AN12: 40 | AO12: 0 | AP12: 6 | AQ12: 40
A13: G107441064ES | B13: Y | C13: 대전 | D13: 대덕구 | E13: 초등학교 | F13: 대전매봉초등학교 | G13: 1G | H13: 2.5G | I13: O | J13: 2 | K13: 2 | L13: 1 | M13: 11 | N13: 3 | O13: 0 | P13: 9 | Q13: 8 | R13: 1 | S13: 0 | T13: 1 | U13: 1 | V13: 0 | W13: 0 | X13: 0 | Y13: 0 | Z13: 17 | AA13: 2 | AB13: 0 | AC13: 0 | AD13: 0 | AE13: 0 | AF13: 0 | AG13: 0 | AH13: 0 | AI13: 1 | AJ13: 1 | AK13: 11 | AL13: 0 | AM13: 20 | AN13: 39 | AO13: 2 | AP13: 3 | AQ13: 63
A14: G107441066ES | B14: Y | C14: 대전 | D14: 대덕구 | E14: 초등학교 | F14: 대전목상초등학교 | G14: 1G | I14: X | J14: 2 | K14: 2 | L14: 1 | M14: 10 | N14: 3 | O14: 0 | P14: 7 | Q14: 7 | R14: 0 | S14: 0 | T14: 0 | U14: 0 | V14: 0 | W14: 0 | X14: 0 | Y14: 0 | Z14: 0 | AA14: 0 | AB14: 0 | AC14: 16 | AD14: 2 | AE14: 0 | AF14: 0 | AG14: 0 | AH14: 0 | AI14: 1 | AJ14: 0 | AK14: 5 | AL14: 0 | AM14: 15 | AN14: 12 | AO14: 0 | AP14: 3 | AQ14: 29
A15: G107441021MS | B15: Y | C15: 대전 | D15: 대덕구 | E15: 중학교 | F15: 대전법동중학교 | G15: 1G | I15: X | J15: 2 | K15: 0 | L15: 0 | M15: 10 | N15: 3 | O15: 1 | P15: 1 | Q15: 1 | R15: 0 | S15: 0 | T15: 0 | U15: 0 | V15: 0 | W15: 0 | X15: 1 | Y15: 1 | Z15: 6 | AA15: 1 | AB15: 6 | AC15: 0 | AD15: 0 | AE15: 0 | AF15: 1 | AG15: 0 | AH15: 1 | AI15: 1 | AJ15: 0 | AK15: 7 | AL15: 1 | AM15: 6 | AN15: 42 | AO15: 3 | AP15: 7 | AQ15: 48
A16: G107441072ES | B16: Y | C16: 대전 | D16: 대덕구 | E16: 초등학교 | F16: 대전법동초등학교 | G16: 1G | I16: O | J16: 2 | K16: 3 | L16: 1 | M16: 3 | N16: 1 | O16: 0 | P16: 12 | Q16: 10 | R16: 2 | S16: 0 | T16: 0 | U16: 0 | V16: 0 | W16: 0 | X16: 0 | Y16: 0 | Z16: 0 | AA16: 0 | AB16: 0 | AC16: 12 | AD16: 2 | AE16: 0 | AF16: 0 | AG16: 0 | AH16: 0 | AI16: 1 | AJ16: 0 | AK16: 7 | AL16: 0 | AM16: 10 | AN16: 22 | AO16: 0 | AP16: 6 | AQ16: 33
A17: G107441075ES | B17: Y | C17: 대전 | D17: 대덕구 | E17: 초등학교 | F17: 대전비래초등학교 | G17: 1G | I17: O | J17: 2 | K17: 3 | L17: 1 | M17: 6 | N17: 1 | O17: 0 | P17: 10 | Q17: 6 | R17: 4 | S17: 0 | T17: 2 | U17: 1 | V17: 0 | W17: 0 | X17: 0 | Y17: 0 | Z17: 9 | AA17: 3 | AB17: 0 | AC17: 0 | AD17: 0 | AE17: 0 | AF17: 0 | AG17: 0 | AH17: 0 | AI17: 1 | AJ17: 0 | AK17: 7 | AL17: 1 | AM17: 0 | AN17: 15 | AO17: 4 | AP17: 4 | AQ17: 17
A18: G107441256ES | B18: Y | C18: 대전 | D18: 대덕구 | E18: 초등학교 | F18: 대전새여울초등학교 | G18: 1G | H18: 2.5G | I18: X | J18: 2 | K18: 1 | L18: 1 | M18: 16 | N18: 7 | O18: 0 | P18: 1 | Q18: 1 | R18: 0 | S18: 0 | T18: 5 | U18: 0 | V18: 0 | W18: 0 | X18: 1 | Y18: 0 | Z18: 11 | AA18: 5 | AB18: 0 | AC18: 0 | AD18: 0 | AE18: 0 | AF18: 0 | AG18: 0 | AH18: 0 | AI18: 1 | AJ18: 1 | AK18: 6 | AL18: 0 | AM18: 2 | AN18: 53 | AO18: 0 | AP18: 5 | AQ18: 58
A19: G107430329HS | B19: Y | C19: 대전 | D19: 대덕구 | E19: 고등학교 | F19: 대전생활과학고등학교 | G19: 1G | I19: X | J19: 2 | K19: 2 | L19: 1 | M19: 8 | N19: 8 | O19: 0 | P19: 3 | Q19: 3 | R19: 0 | S19: 0 | T19: 0 | U19: 0 | V19: 0 | W19: 2 | X19: 2 | Y19: 0 | Z19: 8 | AA19: 5 | AB19: 0 | AC19: 0 | AD19: 0 | AE19: 0 | AF19: 0 | AG19: 0 | AH19: 0 | AI19: 1 | AJ19: 0 | AK19: 10 | AL19: 0 | AM19: 0 | AN19: 60 | AO19: 0 | AP19: 9 | AQ19: 61
A20: G107441079ES | B20: Y | C20: 대전 | D20: 대덕구 | E20: 초등학교 | F20: 대전석봉초등학교 | G20: 1G | I20: O | J20: 2 | K20: 1 | L20: 1 | M20: 5 | N20: 3 | O20: 0 | P20: 3 | Q20: 2 | R20: 1 | S20: 0 | T20: 0 | U20: 0 | V20: 0 | W20: 0 | X20: 0 | Y20: 0 | Z20: 0 | AA20: 0 | AB20: 0 | AC20: 6 | AD20: 3 | AE20: 0 | AF20: 0 | AG20: 0 | AH20: 0 | AI20: 1 | AJ20: 0 | AK20: 4 | AL20: 0 | AM20: 9 | AN20: 7 | AO20: 0 | AP20: 2 | AQ20: 18
A21: G107430132HS | B21: Y | C21: 대전 | D21: 대덕구 | E21: 고등학교 | F21: 대전송촌고등학교 | G21: 1G | H21: 2.5G | I21: X | J21: 2 | K21: 3 | L21: 1 | M21: 14 | N21: 8 | O21: 0 | P21: 15 | Q21: 15 | R21: 0 | S21: 0 | T21: 0 | U21: 1 | V21: 0 | W21: 0 | X21: 0 | Y21: 0 | Z21: 18 | AA21: 2 | AB21: 0 | AC21: 0 | AD21: 0 | AE21: 0 | AF21: 10 | AG21: 4 | AH21: 0 | AI21: 1 | AJ21: 0 | AK21: 11 | AL21: 0 | AM21: 0 | AN21: 53 | AO21: 0 | AP21: 10 | AQ21: 54
A22: G107441022MS | B22: Y | C22: 대전 | D22: 대덕구 | E22: 중학교 | F22: 대전송촌중학교 | G22: 1G | H22: 2.5G | I22: X | J22: 2 | K22: 3 | L22: 1 | M22: 5 | N22: 3 | O22: 0 | P22: 14 | Q22: 10 | R22: 4 | S22: 0 | T22: 3 | U22: 1 | V22: 0 | W22: 0 | X22: 0 | Y22: 0 | Z22: 11 | AA22: 5 | AB22: 0 | AC22: 0 | AD22: 0 | AE22: 0 | AF22: 0 | AG22: 0 | AH22: 0 | AI22: 1 | AJ22: 0 | AK22: 8 | AL22: 0 | AM22: 0 | AN22: 41 | AO22: 0 | AP22: 5 | AQ22: 44
A23: G107441083ES | B23: Y | C23: 대전 | D23: 대덕구 | E23: 초등학교 | F23: 대전송촌초등학교 | G23: 1G | H23: 2.5G | I23: O | J23: 2 | K23: 0 | L23: 0 | M23: 11 | N23: 2 | O23: 1 | P23: 1 | Q23: 1 | R23: 0 | S23: 0 | T23: 0 | U23: 0 | V23: 0 | W23: 0 | X23: 0 | Y23: 0 | Z23: 8 | AA23: 1 | AB23: 6 | AC23: 0 | AD23: 0 | AE23: 0 | AF23: 0 | AG23: 0 | AH23: 0 | AI23: 1 | AJ23: 0 | AK23: 6 | AL23: 0 | AM23: 33 | AN23: 15 | AO23: 0 | AP23: 2 | AQ23: 53
A24: G107441086ES | B24: Y | C24: 대전 | D24: 대덕구 | E24: 초등학교 | F24: 대전양지초등학교 | G24: 1G | I24: O | J24: 2 | K24: 1 | L24: 1 | M24: 11 | N24: 4 | O24: 0 | P24: 5 | Q24: 5 | R24: 0 | S24: 0 | T24: 0 | U24: 0 | V24: 0 | W24: 0 | X24: 0 | Y24: 0 | Z24: 15 | AA24: 3 | AB24: 0 | AC24: 0 | AD24: 0 | AE24: 0 | AF24: 0 | AG24: 0 | AH24: 0 | AI24: 1 | AJ24: 1 | AK24: 2 | AL24: 0 | AM24: 9 | AN24: 27 | AO24: 0 | AP24: 3 | AQ24: 36
A25: G107430357VH | B25: Y | C25: 대전 | D25: 대덕구 | E25: 특수학교 | F25: 대전온라인학교 | G25: 1G | I25: X | J25: 2 | K25: 1 | L25: 1 | M25: 8 | N25: 2 | O25: 0 | P25: 0 | Q25: 0 | R25: 0 | S25: 0 | T25: 0 | U25: 0 | V25: 0 | W25: 1 | X25: 0 | Y25: 0 | Z25: 6 | AA25: 1 | AB25: 0 | AC25: 0 | AD25: 0 | AE25: 0 | AF25: 0 | AG25: 0 | AH25: 0 | AI25: 1 | AJ25: 0 | AK25: 1 | AL25: 0 | AM25: 0 | AN25: 13 | AO25: 0 | AP25: 1 | AQ25: 13
A26: G107441025MS | B26: Y | C26: 대전 | D26: 대덕구 | E26: 중학교 | F26: 대전용전중학교 | G26: 1G | I26: X | J26: 2 | K26: 2 | L26: 1 | M26: 4 | N26: 3 | O26: 0 | P26: 13 | Q26: 13 | R26: 0 | S26: 0 | T26: 0 | U26: 0 | V26: 0 | W26: 0 | X26: 0 | Y26: 0 | Z26: 0 | AA26: 0 | AB26: 0 | AC26: 17 | AD26: 2 | AE26: 0 | AF26: 0 | AG26: 0 | AH26: 0 | AI26: 1 | AJ26: 0 | AK26: 8 | AL26: 0 | AM26: 0 | AN26: 39 | AO26: 0 | AP26: 7 | AQ26: 40
A27: G107430113SS | B27: Y | C27: 대전 | D27: 대덕구 | E27: 특수학교 | F27: 대전원명학교 | G27: 1G | I27: X | J27: 2 | K27: 3 | L27: 1 | M27: 10 | N27: 1 | O27: 0 | P27: 6 | Q27: 6 | R27: 0 | S27: 0 | T27: 2 | U27: 0 | V27: 0 | W27: 0 | X27: 0 | Y27: 0 | Z27: 14 | AA27: 0 | AB27: 0 | AC27: 0 | AD27: 0 | AE27: 0 | AF27: 0 | AG27: 0 | AH27: 0 | AI27: 1 | AJ27: 0 | AK27: 14 | AL27: 0 | AM27: 0 | AN27: 65 | AO27: 3 | AP27: 11 | AQ27: 65
A28: G107430240HS | B28: Y | C28: 대전 | D28: 대덕구 | E28: 고등학교 | F28: 대전이문고등학교 | G28: 1G | I28: X | J28: 2 | K28: 2 | L28: 1 | M28: 7 | N28: 3 | O28: 0 | P28: 8 | Q28: 6 | R28: 2 | S28: 0 | T28: 2 | U28: 3 | V28: 0 | W28: 0 | X28: 0 | Y28: 0 | Z28: 10 | AA28: 1 | AB28: 0 | AC28: 0 | AD28: 0 | AE28: 0 | AF28: 0 | AG28: 0 | AH28: 0 | AI28: 1 | AJ28: 0 | AK28: 11 | AL28: 0 | AM28: 0 | AN28: 64 | AO28: 0 | AP28: 10 | AQ28: 65
A29: G107441095ES | B29: Y | C29: 대전 | D29: 대덕구 | E29: 초등학교 | F29: 대전중리초등학교 | G29: 1G | H29: 2.5G | I29: O | J29: 2 | K29: 1 | L29: 1 | M29: 6 | N29: 3 | O29: 0 | P29: 12 | Q29: 10 | R29: 2 | S29: 0 | T29: 0 | U29: 0 | V29: 0 | W29: 0 | X29: 0 | Y29: 0 | Z29: 0 | AA29: 0 | AB29: 0 | AC29: 0 | AD29: 0 | AE29: 0 | AF29: 15 | AG29: 4 | AH29: 0 | AI29: 1 | AJ29: 0 | AK29: 6 | AL29: 0 | AM29: 23 | AN29: 27 | AO29: 0 | AP29: 5 | AQ29: 51
A30: G107441097ES | B30: Y | C30: 대전 | D30: 대덕구 | E30: 초등학교 | F30: 대전중원초등학교 | G30: 1G | H30: 2.5G | I30: O | J30: 2 | K30: 0 | L30: 0 | M30: 9 | N30: 10 | O30: 1 | P30: 0 | Q30: 0 | R30: 0 | S30: 0 | T30: 1 | U30: 0 | V30: 0 | W30: 0 | X30: 1 | Y30: 0 | Z30: 5 | AA30: 7 | AB30: 6 | AC30: 0 | AD30: 0 | AE30: 0 | AF30: 0 | AG30: 0 | AH30: 0 | AI30: 1 | AJ30: 0 | AK30: 8 | AL30: 1 | AM30: 26 | AN30: 26 | AO30: 2 | AP30: 4 | AQ30: 56
A31: G107430349SS | B31: Y | C31: 대전 | D31: 대덕구 | E31: 특수학교 | F31: 대전해든학교 | G31: 1G | I31: X | J31: 2 | K31: 12 | L31: 11 | M31: 17 | N31: 10 | O31: 0 | P31: 3 | Q31: 2 | R31: 1 | S31: 0 | T31: 0 | U31: 0 | V31: 0 | W31: 0 | X31: 0 | Y31: 0 | Z31: 18 | AA31: 10 | AB31: 0 | AC31: 0 | AD31: 0 | AE31: 0 | AF31: 0 | AG31: 0 | AH31: 0 | AI31: 1 | AJ31: 0 | AK31: 6 | AL31: 0 | AM31: 0 | AN31: 58 | AO31: 0 | AP31: 6 | AQ31: 58
A32: G107441103ES | B32: Y | C32: 대전 | D32: 대덕구 | E32: 초등학교 | F32: 대전화정초등학교 | G32: 1G | I32: X | J32: 2 | K32: 1 | L32: 1 | M32: 8 | N32: 1 | O32: 0 | P32: 17 | Q32: 13 | R32: 4 | S32: 0 | T32: 0 | U32: 0 | V32: 0 | W32: 0 | X32: 0 | Y32: 0 | Z32: 0 | AA32: 0 | AB32: 0 | AC32: 0 | AD32: 0 | AE32: 0 | AF32: 21 | AG32: 5 | AH32: 0 | AI32: 1 | AJ32: 1 | AK32: 6 | AL32: 0 | AM32: 13 | AN32: 25 | AO32: 0 | AP32: 6 | AQ32: 39
A33: G107430039HS | B33: Y | C33: 대전 | D33: 대덕구 | E33: 고등학교 | F33: 동대전고등학교 | G33: 1G | H33: 2.5G | I33: X | J33: 2 | K33: 1 | L33: 1 | M33: 19 | N33: 4 | O33: 0 | P33: 0 | Q33: 0 | R33: 0 | S33: 0 | T33: 0 | U33: 0 | V33: 0 | W33: 0 | X33: 0 | Y33: 0 | Z33: 18 | AA33: 3 | AB33: 0 | AC33: 0 | AD33: 0 | AE33: 0 | AF33: 0 | AG33: 0 | AH33: 0 | AI33: 1 | AJ33: 0 | AK33: 6 | AL33: 0 | AM33: 0 | AN33: 47 | AO33: 0 | AP33: 5 | AQ33: 48
A34: G107441110ES | B34: Y | C34: 대전 | D34: 대덕구 | E34: 초등학교 | F34: 새일초등학교 | G34: 1G | I34: O | J34: 2 | K34: 1 | L34: 1 | M34: 7 | N34: 1 | O34: 0 | P34: 6 | Q34: 2 | R34: 4 | S34: 0 | T34: 0 | U34: 0 | V34: 0 | W34: 0 | X34: 0 | Y34: 0 | Z34: 0 | AA34: 0 | AB34: 0 | AC34: 9 | AD34: 4 | AE34: 0 | AF34: 0 | AG34: 0 | AH34: 0 | AI34: 1 | AJ34: 0 | AK34: 11 | AL34: 0 | AM34: 19 | AN34: 19 | AO34: 0 | AP34: 7 | AQ34: 42
A35: G107441036MS | B35: Y | C35: 대전 | D35: 대덕구 | E35: 중학교 | F35: 신탄중앙중학교 | G35: 1G | I35: X | J35: 2 | K35: 1 | L35: 1 | M35: 11 | N35: 3 | O35: 0 | P35: 0 | Q35: 0 | R35: 0 | S35: 0 | T35: 0 | U35: 0 | V35: 0 | W35: 0 | X35: 0 | Y35: 0 | Z35: 10 | AA35: 2 | AB35: 0 | AC35: 0 | AD35: 0 | AE35: 0 | AF35: 0 | AG35: 0 | AH35: 0 | AI35: 1 | AJ35: 0 | AK35: 5 | AL35: 0 | AM35: 0 | AN35: 27 | AO35: 0 | AP35: 4 | AQ35: 28
A36: G107430041HS | B36: Y | C36: 대전 | D36: 대덕구 | E36: 고등학교 | F36: 신탄진고등학교 | G36: 1G | I36: O | J36: 2 | K36: 1 | L36: 1 | M36: 11 | N36: 5 | O36: 0 | P36: 6 | Q36: 3 | R36: 3 | S36: 0 | T36: 0 | U36: 0 | V36: 0 | W36: 0 | X36: 0 | Y36: 0 | Z36: 0 | AA36: 0 | AB36: 0 | AC36: 13 | AD36: 7 | AE36: 0 | AF36: 0 | AG36: 0 | AH36: 0 | AI36: 1 | AJ36: 0 | AK36: 5 | AL36: 0 | AM36: 0 | AN36: 43 | AO36: 0 | AP36: 5 | AQ36: 43
A37: G107441113ES | B37: Y | C37: 대전 | D37: 대덕구 | E37: 초등학교 | F37: 신탄진용정초등학교 | G37: 1G | H37: 2.5G | I37: X | J37: 2 | K37: 1 | L37: 1 | M37: 10 | N37: 3 | O37: 0 | P37: 0 | Q37: 0 | R37: 0 | S37: 0 | T37: 1 | U37: 1 | V37: 0 | W37: 0 | X37: 0 | Y37: 0 | Z37: 5 | AA37: 0 | AB37: 0 | AC37: 0 | AD37: 0 | AE37: 0 | AF37: 4 | AG37: 1 | AH37: 0 | AI37: 1 | AJ37: 0 | AK37: 6 | AL37: 0 | AM37: 14 | AN37: 20 | AO37: 2 | AP37: 3 | AQ37: 35
A38: G107441037MS | B38: Y | C38: 대전 | D38: 대덕구 | E38: 중학교 | F38: 신탄진중학교 | G38: 1G | I38: X | J38: 2 | K38: 3 | L38: 1 | M38: 21 | N38: 3 | O38: 0 | P38: 3 | Q38: 3 | R38: 0 | S38: 0 | T38: 0 | U38: 0 | V38: 0 | W38: 1 | X38: 0 | Y38: 0 | Z38: 23 | AA38: 2 | AB38: 0 | AC38: 0 | AD38: 0 | AE38: 0 | AF38: 0 | AG38: 0 | AH38: 0 | AI38: 1 | AJ38: 0 | AK38: 7 | AL38: 0 | AM38: 0 | AN38: 29 | AO38: 0 | AP38: 3 | AQ38: 30
A39: G107441114ES | B39: Y | C39: 대전 | D39: 대덕구 | E39: 초등학교 | F39: 신탄진초등학교 | G39: 1G | I39: X | J39: 2 | K39: 2 | L39: 2 | M39: 14 | N39: 1 | O39: 0 | P39: 21 | Q39: 18 | R39: 3 | S39: 0 | T39: 0 | U39: 0 | V39: 0 | W39: 0 | X39: 0 | Y39: 0 | Z39: 31 | AA39: 3 | AB39: 0 | AC39: 0 | AD39: 0 | AE39: 0 | AF39: 0 | AG39: 0 | AH39: 0 | AI39: 1 | AJ39: 2 | AK39: 11 | AL39: 0 | AM39: 5 | AN39: 48 | AO39: 0 | AP39: 5 | AQ39: 57
A40: G107441038MS | B40: Y | C40: 대전 | D40: 대덕구 | E40: 중학교 | F40: 오정중학교 | G40: 1G | I40: X | J40: 2 | K40: 1 | L40: 1 | M40: 9 | N40: 2 | O40: 2 | P40: 15 | Q40: 11 | R40: 3 | S40: 1 | T40: 0 | U40: 0 | V40: 0 | W40: 0 | X40: 0 | Y40: 0 | Z40: 0 | AA40: 0 | AB40: 0 | AC40: 18 | AD40: 4 | AE40: 6 | AF40: 0 | AG40: 0 | AH40: 0 | AI40: 1 | AJ40: 0 | AK40: 6 | AL40: 0 | AM40: 0 | AN40: 20 | AO40: 0 | AP40: 5 | AQ40: 20
...

Sheet 케이블통계
D1: =SUBTOTAL(9,D4:D721) -> 6506 | E1: =SUBTOTAL(9,E4:E721) -> 3717 | F1: =SUBTOTAL(9,F4:F721) -> 42551 | G1: =SUBTOTAL(9,G4:G721) -> 52395 | H1: =SUBTOTAL(9,H4:H721) -> 8098 | I1: =SUBTOTAL(9,I4:I721) -> 1866 | J1: =SUBTOTAL(9,J4:J721) -> 754 | K1: =SUBTOTAL(9,K4:K721) -> 239 | ... AB1: =SUBTOTAL(9,AB4:AB721) -> 12
A2: 힉교코드 | B2: 학교 | C2: 지역명 | D2: SM | E2: MM | F2: UTP Cat.6 | G2: UTP Cat.5e | H2: UTP Cat.5 | I2: SM | J2: SM | K2: SM | L2: SM | M2: MM | N2: MM | O2: MM | P2: MM | Q2: UTP Cat.5e | R2: UTP Cat.5e | S2: UTP Cat.5e | T2: UTP Cat.5 | U2: UTP Cat.6 | V2: UTP Cat.6 | W2: UTP Cat.6 | X2: UTP Cat.5 | Y2: UTP Cat.5 | Z2: UTP Cat.5 | AA2: UTP Cat.5 | AB2: UTP Cat.5
D3: 합계 | E3: 합계 | F3: 합계 | G3: 합계 | H3: 합계 | I3: 업무망 | J3: 교육망 | K3: 기타 | L3: 무선망 | M3: 업무망 | N3: 교육망 | O3: 기타 | P3: 무선망 | Q3: 업무망 | R3: 교육망 | S3: 기타 | T3: 무선망 | U3: 업무망 | V3: 교육망 | W3: 기타 | X3: 무선망 | Y3: 업무망 | Z3: 교육망 | AA3: 기타 | AB3: 무선망
A4: N108222061ES | B4: 금암초등학교 | C4: 계룡 | D4: 7 | E4: 13 | F4: 4 | G4: 345 | H4: 0 | I4: 2 | J4: 0 | K4: 0 | L4: 5 | M4: 11 | N4: 1 | O4: 0 | P4: 1 | Q4: 221 | R4: 124 | S4: 0 | T4: 0 | U4: 2 | V4: 2 | W4: 0 | X4: 0 | Y4: 0 | Z4: 0 | AA4: 0 | AB4: 0
A5: N108222036ES | B5: 두마초등학교 | C5: 계룡 | D5: 7 | E5: 19 | F5: 6 | G5: 181 | H5: 0 | I5: 0 | J5: 0 | K5: 0 | L5: 7 | M5: 18 | N5: 0 | O5: 0 | P5: 1 | Q5: 181 | R5: 0 | S5: 0 | T5: 0 | U5: 3 | V5: 3 | W5: 0 | X5: 0 | Y5: 0 | Z5: 0 | AA5: 0 | AB5: 0
A6: N108222019ES | B6: 신도초등학교 | C6: 계룡 | D6: 7 | E6: 1 | F6: 8 | G6: 186 | H6: 0 | I6: 0 | J6: 0 | K6: 0 | L6: 7 | M6: 0 | N6: 0 | O6: 0 | P6: 1 | Q6: 178 | R6: 8 | S6: 0 | T6: 0 | U6: 6 | V6: 2 | W6: 0 | X6: 0 | Y6: 0 | Z6: 0 | AA6: 0 | AB6: 0
A7: N108222046ES | B7: 엄사초등학교 | C7: 계룡 | D7: 9 | E7: 1 | F7: 10 | G7: 172 | H7: 0 | I7: 0 | J7: 0 | K7: 0 | L7: 9 | M7: 0 | N7: 0 | O7: 0 | P7: 1 | Q7: 139 | R7: 33 | S7: 0 | T7: 0 | U7: 8 | V7: 2 | W7: 0 | X7: 0 | Y7: 0 | Z7: 0 | AA7: 0 | AB7: 0
A8: N108222051ES | B8: 용남초등학교 | C8: 계룡 | D8: 6 | E8: 1 | F8: 110 | G8: 84 | H8: 0 | I8: 0 | J8: 0 | K8: 0 | L8: 6 | M8: 0 | N8: 0 | O8: 0 | P8: 1 | Q8: 48 | R8: 36 | S8: 0 | T8: 0 | U8: 15 | V8: 95 | W8: 0 | X8: 0 | Y8: 0 | Z8: 0 | AA8: 0 | AB8: 0
A9: N108222119MS | B9: 계룡중학교 | C9: 계룡 | D9: 6 | E9: 19 | F9: 6 | G9: 215 | H9: 78 | I9: 0 | J9: 0 | K9: 0 | L9: 6 | M9: 17 | N9: 1 | O9: 0 | P9: 1 | Q9: 137 | R9: 78 | S9: 0 | T9: 0 | U9: 3 | V9: 3 | W9: 0 | X9: 0 | Y9: 78 | Z9: 0 | AA9: 0 | AB9: 0
A10: N108222017MS | B10: 엄사중학교 | C10: 계룡 | D10: 8 | E10: 3 | F10: 8 | G10: 154 | H10: 43 | I10: 0 | J10: 0 | K10: 0 | L10: 8 | M10: 2 | N10: 0 | O10: 0 | P10: 1 | Q10: 145 | R10: 9 | S10: 0 | T10: 0 | U10: 4 | V10: 4 | W10: 0 | X10: 0 | Y10: 43 | Z10: 0 | AA10: 0 | AB10: 0
A11: N108222012MS | B11: 용남중학교 | C11: 계룡 | D11: 7 | E11: 1 | F11: 36 | G11: 28 | H11: 0 | I11: 1 | J11: 1 | K11: 0 | L11: 5 | M11: 0 | N11: 0 | O11: 0 | P11: 1 | Q11: 25 | R11: 3 | S11: 0 | T11: 0 | U11: 32 | V11: 4 | W11: 0 | X11: 0 | Y11: 0 | Z11: 0 | AA11: 0 | AB11: 0
A12: N108140237HS | B12: 계룡고등학교 | C12: 계룡 | D12: 14 | E12: 1 | F12: 36 | G12: 116 | H12: 209 | I12: 4 | J12: 4 | K12: 0 | L12: 6 | M12: 0 | N12: 0 | O12: 0 | P12: 1 | Q12: 84 | R12: 32 | S12: 0 | T12: 0 | U12: 9 | V12: 27 | W12: 0 | X12: 0 | Y12: 144 | Z12: 65 | AA12: 0 | AB12: 0
A13: N108140063HS | B13: 용남고등학교 | C13: 계룡 | D13: 6 | E13: 1 | F13: 5 | G13: 73 | H13: 0 | I13: 0 | J13: 0 | K13: 0 | L13: 6 | M13: 0 | N13: 0 | O13: 0 | P13: 1 | Q13: 47 | R13: 26 | S13: 0 | T13: 0 | U13: 3 | V13: 2 | W13: 0 | X13: 0 | Y13: 0 | Z13: 0 | AA13: 0 | AB13: 0
A14: N10C035902MS | B14: 국립공주대학교사범대학부설중학교 | C14: 공주 | D14: 0 | E14: 3 | F14: 5 | G14: 17 | H14: 0 | I14: 0 | J14: 0 | K14: 0 | L14: 0 | M14: 1 | N14: 0 | O14: 0 | P14: 2 | Q14: 16 | R14: 1 | S14: 0 | T14: 0 | U14: 3 | V14: 2 | W14: 0 | X14: 0 | Y14: 0 | Z14: 0 | AA14: 0 | AB14: 0
A15: N10C035903HS | B15: 국립공주대학교사범대학부설고등학교 | C15: 공주 | D15: 0 | E15: 9 | F15: 22 | G15: 15 | H15: 0 | I15: 0 | J15: 0 | K15: 0 | L15: 0 | M15: 7 | N15: 0 | O15: 0 | P15: 2 | Q15: 14 | R15: 1 | S15: 0 | T15: 0 | U15: 20 | V15: 2 | W15: 0 | X15: 0 | Y15: 0 | Z15: 0 | AA15: 0 | AB15: 0
... A721: N108261098ES | B721: 한울초등학교 | C721: 홍성 | D721: 4 | E721: 33 | F721: 9 | G721: 247 | H721: 0 | I721: 0 | J721: 0 | K721: 0 | L721: 4 | M721: 19 | N721: 5 | O721: 8 | P721: 1 | Q721: 121 | R721: 44 | S721: 82 | T721: 0 | U721: 6 | V721: 3 | W721: 0 | X721: 0 | Y721: 0 | Z721: 0 | AA721: 0 | AB721: 0

Sheet POE
A1: 학교코드 | B1: 학교명 | C1: 최대사용포트수 | D1: 채널 중첩수
A2: N108140237HS | B2: 계룡고등학교 | C2: 9 | D2: 1.07
A3: N108222119MS | B3: 계룡중학교 | C3: 8 | D3: 0
A4: N108222061ES | B4: 금암초등학교 | C4: 7 | D4: 0
A5: N108222036ES | B5: 두마초등학교 | C5: 9 | D5: 0.21
A6: N108222019ES | B6: 신도초등학교 | C6: 5 | D6: 1.04
A7: N108222017MS | B7: 엄사중학교 | C7: 9 | D7: 0.03
A8: N108222046ES | B8: 엄사초등학교 | C8: 6 | D8: 1
A9: N108140063HS | B9: 용남고등학교 | C9: 14 | D9: 0.59
A10: N108222012MS | B10: 용남중학교 | C10: 6 | D10: 1.27
A11: N108222051ES | B11: 용남초등학교 | C11: 11 | D11: 0.65
A12: N108161016MS | B12: 경천중학교 | C12: 5 | D12: 0.34
A13: N108161021ES | B13: 경천초등학교 | C13: 6 | D13: 1.27
... A245: N108171043ES | B245: 천북초등학교 | C245: 6 | D245: 0.8
A246: N108171014MS | B246: 청라중학교 | C246: 10 | D246: x
A247: N108171044ES | B247: 청라초등학교 | C247: 5 | D247: x
A248: N108171045ES | B248: 청룡초등학교 | C248: 4 | D248: 1.1666
A249: N108171051ES | B249: 청룡초등학교장고분교장 | C249: 3 | D249: 1.02
A250: N108171046ES | B250: 청보초등학교 | C250: 4 | D250: x
A251: N108171047ES | B251: 청소초등학교 | C251: 0 | D251: 0
A252: N108171048ES | B252: 청파초등학교 | C252: 4 | D252: 2
A253: N108171103ES | B253: 청파초등학교외연도분교장 | C253: 0 | D253: 2.3
A254: N108140206HS | B254: 충남해양과학고등학교 | C254: 8 | D254: 2.78
A255: N108171015MS | B255: 한내여자중학교 | C255: 9 | D255: 0.01
A256: N108171049ES | B256: 한내초등학교 | C256: 8 | D256: 8.1438
A257: N108231017ES | B257: 구룡초등학교 | C257: 5 | D257: 2.5588
A258: N108231018ES | B258: 궁남초등학교 | C258: 8 | D258: 1.707
A259: N108231019ES | B259: 규암초등학교 | C259: 11 | D259: 4.09
A260: N108231022ES | B260: 내산초등학교 | C260: 4 | D260: 4.5185
A261: N108231023ES | B261: 대왕초등학교 | C261: 7 | D261: 4.06
A262: N108231025ES | B262: 백강초등학교 | C262: 8 | D262: 2.4375
... A568: N108151074ES | B568: 천안봉서초등학교 | C568: 10 | D568: 1.05
A569: N108151075ES | B569: 천안부대초등학교 | C569: 5 | D569: 이미지 오류
A570: N108151017MS | B570: 천안부성중학교 | C570: 10 | D570: 1.37
A571: N108151086ES | B571: 천안부성초등학교 | C571: 11 | D571: 2.753
A572: N108151087ES | B572: 천안부영초등학교 | C572: 7 | D572: 1.851
A573: N108151018MS | B573: 천안북중학교 | C573: 5 | D573: 1.0838
A574: N108140387HS | B574: 천안불당고등학교 | C574: 11 | D574: 1.75
A575: N108151010MS | B575: 천안불당중학교 | C575: 11 | D575: 4.5097
A576: N108151036ES | B576: 천안불당초등학교 | C576: 12 | D576: 4.46
...

Sheet 대전AP
A1: 학교코드 | B1: 지역 | C1: 학교명 | D1: n | E1: ac | F1: ax | G1: 위치 5 | H1: 위치 5 외
A2: N108140237HS | B2: 계룡 | C2: 계룡고등학교 | D2: 0 | E2: 0 | F2: 39 | G2: 16 | H2: 23
A3: N108222119MS | B3: 계룡 | C3: 계룡중학교 | D3: 0 | E3: 0 | F3: 30 | G3: 7 | H3: 23
A4: N108222061ES | B4: 계룡 | C4: 금암초등학교 | D4: 0 | E4: 0 | F4: 25 | G4: 20 | H4: 5
A5: N108222036ES | B5: 계룡 | C5: 두마초등학교 | D5: 0 | E5: 0 | F5: 33 | G5: 32 | H5: 1
A6: N108222019ES | B6: 계룡 | C6: 신도초등학교 | D6: 0 | E6: 0 | F6: 26 | G6: 6 | H6: 20
A7: N108222017MS | B7: 계룡 | C7: 엄사중학교 | D7: 0 | E7: 0 | F7: 38 | G7: 5 | H7: 33
A8: N108222046ES | B8: 계룡 | C8: 엄사초등학교 | D8: 0 | E8: 0 | F8: 30 | G8: 10 | H8: 20
A9: N108140063HS | B9: 계룡 | C9: 용남고등학교 | D9: 0 | E9: 0 | F9: 54 | G9: 46 | H9: 8
A10: N108222012MS | B10: 계룡 | C10: 용남중학교 | D10: 0 | E10: 0 | F10: 32 | G10: 29 | H10: 3
A11: N108222051ES | B11: 계룡 | C11: 용남초등학교 | D11: 0 | E11: 0 | F11: 44 | G11: 4 | H11: 40
A12: N108161016MS | B12: 공주 | C12: 경천중학교 | D12: 0 | E12: 0 | F12: 9 | G12: 3 | H12: 4
A13: N108161021ES | B13: 공주 | C13: 경천초등학교 | D13: 0 | E13: 2 | F13: 6 | G13: 6 | H13: 0
... A720: N108261015MS | B720: 홍성 | C720: 홍주중학교 | D720: 0 | E720: 0 | F720: 30 | G720: 7 | H720: 23

Sheet Sheet1
A1: 학교코드 | B1: 지역 | C1: 학교명
A2: G107441266MS | B2: 대덕구 | C2: 대전경덕중학교
A3: G107441056ES | B3: 대덕구 | C3: 대전대양초등학교
A4: G107441016MS | B4: 대덕구 | C4: 대전대청중학교
A5: G107441017MS | B5: 대덕구 | C5: 대전대화중학교
A6: G107441057ES | B6: 대덕구 | C6: 대전대화초등학교
A7: G107441060ES | B7: 대덕구 | C7: 대전동도초등학교
A8: G107441062ES | B8: 대덕구 | C8: 대전동산초등학교
A9: G107441019MS | B9: 대덕구 | C9: 대전매봉중학교
A10: G107441064ES | B10: 대덕구 | C10: 대전매봉초등학교
A11: G107441066ES | B11: 대덕구 | C11: 대전목상초등학교
A12: G107441021MS | B12: 대덕구 | C12: 대전법동중학교
... A316: G107451353ES | B316: 서구 | C316: 대전탄방초등학교용문분교장
