Workbook

Sheet 대전
K1: 방화벽 | L1: 보안L2/L3 | N1: L2SW | Q1: L2SW(100M) | T1: 광케이블MM | W1: 광케이블SM | Z1: Cat6 | AC1: Cat5E | AF1: Cat5 | AI1: L2SW(10G) | AJ1: L2PoE(2.5G이상) | AK1: L2PoE(1G이상) | AL1: 기타L2/L3 | AM1: 무선AP5이하 | AN1: 무선AP6이상 | AO1: 광케이블MM_무선 | AP1: 광케이블SM_무선 | AQ1: Cat6_무선
A2: 배포순서 | B2: 학교코드 | C2: 사업대상 | D2: 교육청 | E2: 지역 | F2: 학교유형 | G2: 학교명 | H2: 스쿨넷 회선속도 | I2: 무선망 전용 회선속도 | J2: 망분리현황 | K2: 스쿨넷 | L2: 업무망 | M2: 교육망 | N2: 업무망 | O2: 교육망 | P2: 기타 | Q2: 업무망 | R2: 교육망 | S2: 기타 | T2: 업무망 | U2: 교육망 | V2: 기타 | W2: 업무망 | X2: 교육망 | Y2: 기타 | Z2: 업무망 | AA2: 교육망 | AB2: 기타 | AC2: 업무망 | AD2: 교육망 | AE2: 기타 | AF2: 업무망 | AG2: 교육망 | AH2: 기타 | AI2: 무선망 | AJ2: 무선망 | AK2: 무선망 | AL2: 무선망 | AM2: 무선망 | AN2: 무선망 | AO2: 무선망 | AP2: 무선망 | AQ2: 무선망
A3: 1 | B3: G107441266MS | C3: Y | D3: 대전 | E3: 대덕구 | F3: 중학교 | G3: 대전경덕중학교 | H3: 1G | J3: O | K3: 2 | L3: 0 | M3: 0 | N3: 10 | O3: 3 | P3: 1 | Q3: 0 | R3: 0 | S3: 0 | T3: 2 | U3: 1 | V3: 0 | W3: 0 | X3: 0 | Y3: 0 | Z3: 4 | AA3: 1 | AB3: 5 | AC3: 0 | AD3: 0 | AE3: 0 | AF3: 0 | AG3: 0 | AH3: 0 | AI3: 1 | AJ3: 0 | AK3: 6 | AL3: 1 | AM3: 0 | AN3: 23 | AO3: 2 | AP3: 5 | AQ3: 24
A4: 2 | B4: G107441056ES | C4: Y | D4: 대전 | E4: 대덕구 | F4: 초등학교 | G4: 대전대양초등학교 | H4: 1G | J4: O | K4: 2 | L4: 1 | M4: 1 | N4: 15 | O4: 1 | P4: 0 | Q4: 1 | R4: 2 | S4: 0 | T4: 0 | U4: 0 | V4: 0 | W4: 0 | X4: 0 | Y4: 0 | Z4: 0 | AA4: 0 | AB4: 0 | AC4: 0 | AD4: 0 | AE4: 0 | AF4: 15 | AG4: 2 | AH4: 0 | AI4: 1 | AJ4: 1 | AK4: 4 | AL4: 0 | AM4: 18 | AN4: 32 | AO4: 0 | AP4: 4 | AQ4: 51
A5: 3 | B5: G107441016MS | C5: Y | D5: 대전 | E5: 대덕구 | F5: 중학교 | G5: 대전대청중학교 | H5: 1G | J5: X | K5: 2 | L5: 1 | M5: 2 | N5: 21 | O5: 5 | P5: 0 | Q5: 1 | R5: 1 | S5: 0 | T5: 2 | U5: 1 | V5: 0 | W5: 0 | X5: 0 | Y5: 0 | Z5: 20 | AA5: 4 | AB5: 0 | AC5: 0 | AD5: 0 | AE5: 0 | AF5: 0 | AG5: 0 | AH5: 0 | AI5: 1 | AJ5: 0 | AK5: 7 | AL5: 0 | AM5: 1 | AN5: 32 | AO5: 1 | AP5: 3 | AQ5: 33
A6: 4 | B6: G107441017MS | C6: Y | D6: 대전 | E6: 대덕구 | F6: 중학교 | G6: 대전대화중학교 | H6: 1G | J6: X | K6: 2 | L6: 1 | M6: 1 | N6: 11 | O6: 2 | P6: 0 | Q6: 3 | R6: 1 | S6: 0 | T6: 0 | U6: 0 | V6: 0 | W6: 0 | X6: 0 | Y6: 0 | Z6: 0 | AA6: 0 | AB6: 0 | AC6: 13 | AD6: 2 | AE6: 0 | AF6: 0 | AG6: 0 | AH6: 0 | AI6: 1 | AJ6: 0 | AK6: 5 | AL6: 0 | AM6: 0 | AN6: 24 | AO6: 0 | AP6: 4 | AQ6: 25
A7: 5 | B7: G107441057ES | C7: Y | D7: 대전 | E7: 대덕구 | F7: 초등학교 | G7: 대전대화초등학교 | H7: 1G | J7: O | K7: 2 | L7: 3 | M7: 1 | N7: 6 | O7: 2 | P7: 0 | Q7: 4 | R7: 2 | S7: 0 | T7: 0 | U7: 0 | V7: 0 | W7: 1 | X7: 1 | Y7: 0 | Z7: 8 | AA7: 2 | AB7: 0 | AC7: 0 | AD7: 0 | AE7: 0 | AF7: 0 | AG7: 0 | AH7: 0 | AI7: 1 | AJ7: 1 | AK7: 3 | AL7: 0 | AM7: 14 | AN7: 11 | AO7: 0 | AP7: 2 | AQ7: 27
A8: 6 | B8: G107441060ES | C8: Y | D8: 대전 | E8: 대덕구 | F8: 초등학교 | G8: 대전동도초등학교 | H8: 1G | J8: X | K8: 2 | L8: 3 | M8: 1 | N8: 7 | O8: 4 | P8: 0 | Q8: 8 | R8: 0 | S8: 0 | T8: 1 | U8: 1 | V8: 0 | W8: 0 | X8: 0 | Y8: 0 | Z8: 0 | AA8: 0 | AB8: 0 | AC8: 13 | AD8: 2 | AE8: 0 | AF8: 0 | AG8: 0 | AH8: 0 | AI8: 1 | AJ8: 1 | AK8: 3 | AL8: 0 | AM8: 11 | AN8: 8 | AO8: 1 | AP8: 2 | AQ8: 20
A9: 7 | B9: G107441062ES | C9: Y | D9: 대전 | E9: 대덕구 | F9: 초등학교 | G9: 대전동산초등학교 | H9: 1G | J9: O | K9: 2 | L9: 1 | M9: 2 | N9: 7 | O9: 1 | P9: 0 | Q9: 3 | R9: 2 | S9: 0 | T9: 0 | U9: 0 | V9: 0 | W9: 0 | X9: 0 | Y9: 0 | Z9: 0 | AA9: 0 | AB9: 0 | AC9: 9 | AD9: 2 | AE9: 0 | AF9: 0 | AG9: 0 | AH9: 0 | AI9: 1 | AJ9: 1 | AK9: 6 | AL9: 0 | AM9: 12 | AN9: 35 | AO9: 0 | AP9: 5 | AQ9: 49
A10: 8 | B10: G107441019MS | C10: Y | D10: 대전 | E10: 대덕구 | F10: 중학교 | G10: 대전매봉중학교 | H10: 1G | I10: 2.5G | J10: X | K10: 2 | L10: 2 | M10: 1 | N10: 9 | O10: 4 | P10: 0 | Q10: 3 | R10: 0 | S10: 0 | T10: 0 | U10: 1 | V10: 0 | W10: 0 | X10: 0 | Y10: 0 | Z10: 11 | AA10: 2 | AB10: 0 | AC10: 0 | AD10: 0 | AE10: 0 | AF10: 0 | AG10: 0 | AH10: 0 | AI10: 1 | AJ10: 0 | AK10: 6 | AL10: 0 | AM10: 0 | AN10: 40 | AO10: 0 | AP10: 6 | AQ10: 40
A11: 9 | B11: G107441064ES | C11: Y | D11: 대전 | E11: 대덕구 | F11: 초등학교 | G11: 대전매봉초등학교 | H11: 1G | I11: 2.5G | J11: O | K11: 2 | L11: 2 | M11: 1 | N11: 11 | O11: 3 | P11: 0 | Q11: 8 | R11: 1 | S11: 0 | T11: 1 | U11: 1 | V11: 0 | W11: 0 | X11: 0 | Y11: 0 | Z11: 17 | AA11: 2 | AB11: 0 | AC11: 0 | AD11: 0 | AE11: 0 | AF11: 0 | AG11: 0 | AH11: 0 | AI11: 1 | AJ11: 1 | AK11: 11 | AL11: 0 | AM11: 20 | AN11: 39 | AO11: 2 | AP11: 3 | AQ11: 63
A12: 10 | B12: G107441066ES | C12: Y | D12: 대전 | E12: 대덕구 | F12: 초등학교 | G12: 대전목상초등학교 | H12: 1G | J12: X | K12: 2 | L12: 2 | M12: 1 | N12: 10 | O12: 3 | P12: 0 | Q12: 7 | R12: 0 | S12: 0 | T12: 0 | U12: 0 | V12: 0 | W12: 0 | X12: 0 | Y12: 0 | Z12: 0 | AA12: 0 | AB12: 0 | AC12: 16 | AD12: 2 | AE12: 0 | AF12: 0 | AG12: 0 | AH12: 0 | AI12: 1 | AJ12: 0 | AK12: 5 | AL12: 0 | AM12: 15 | AN12: 12 | AO12: 0 | AP12: 3 | AQ12: 29
A13: 11 | B13: G107441021MS | C13: Y | D13: 대전 | E13: 대덕구 | F13: 중학교 | G13: 대전법동중학교 | H13: 1G | J13: X | K13: 2 | L13: 0 | M13: 0 | N13: 10 | O13: 3 | P13: 1 | Q13: 1 | R13: 0 | S13: 0 | T13: 0 | U13: 0 | V13: 0 | W13: 0 | X13: 1 | Y13: 1 | Z13: 6 | AA13: 1 | AB13: 6 | AC13: 0 | AD13: 0 | AE13: 0 | AF13: 1 | AG13: 0 | AH13: 1 | AI13: 1 | AJ13: 0 | AK13: 7 | AL13: 1 | AM13: 6 | AN13: 42 | AO13: 3 | AP13: 7 | AQ13: 48
A14: 12 | B14: G107441072ES | C14: Y | D14: 대전 | E14: 대덕구 | F14: 초등학교 | G14: 대전법동초등학교 | H14: 1G | J14: O | K14: 2 | L14: 3 | M14: 1 | N14: 3 | O14: 1 | P14: 0 | Q14: 10 | R14: 2 | S14: 0 | T14: 0 | U14: 0 | V14: 0 | W14: 0 | X14: 0 | Y14: 0 | Z14: 0 | AA14: 0 | AB14: 0 | AC14: 12 | AD14: 2 | AE14: 0 | AF14: 0 | AG14: 0 | AH14: 0 | AI14: 1 | AJ14: 0 | AK14: 7 | AL14: 0 | AM14: 10 | AN14: 22 | AO14: 0 | AP14: 6 | AQ14: 33
A15: 13 | B15: G107441075ES | C15: Y | D15: 대전 | E15: 대덕구 | F15: 초등학교 | G15: 대전비래초등학교 | H15: 1G | J15: O | K15: 2 | L15: 3 | M15: 1 | N15: 6 | O15: 1 | P15: 0 | Q15: 6 | R15: 4 | S15: 0 | T15: 2 | U15: 1 | V15: 0 | W15: 0 | X15: 0 | Y15: 0 | Z15: 9 | AA15: 3 | AB15: 0 | AC15: 0 | AD15: 0 | AE15: 0 | AF15: 0 | AG15: 0 | AH15: 0 | AI15: 1 | AJ15: 0 | AK15: 7 | AL15: 1 | AM15: 0 | AN15: 15 | AO15: 4 | AP15: 4 | AQ15: 17
A16: 14 | B16: G107441256ES | C16: Y | D16: 대전 | E16: 대덕구 | F16: 초등학교 | G16: 대전새여울초등학교 | H16: 1G | I16: 2.5G | J16: X | K16: 2 | L16: 1 | M16: 1 | N16: 16 | O16: 7 | P16: 0 | Q16: 1 | R16: 0 | S16: 0 | T16: 5 | U16: 0 | V16: 0 | W16: 0 | X16: 1 | Y16: 0 | Z16: 11 | AA16: 5 | AB16: 0 | AC16: 0 | AD16: 0 | AE16: 0 | AF16: 0 | AG16: 0 | AH16: 0 | AI16: 1 | AJ16: 1 | AK16: 6 | AL16: 0 | AM16: 2 | AN16: 53 | AO16: 0 | AP16: 5 | AQ16: 58
A17: 15 | B17: G107430329HS | C17: Y | D17: 대전 | E17: 대덕구 | F17: 고등학교 | G17: 대전생활과학고등학교 | H17: 1G | J17: X | K17: 2 | L17: 2 | M17: 1 | N17: 8 | O17: 8 | P17: 0 | Q17: 3 | R17: 0 | S17: 0 | T17: 0 | U17: 0 | V17: 0 | W17: 2 | X17: 2 | Y17: 0 | Z17: 8 | AA17: 5 | AB17: 0 | AC17: 0 | AD17: 0 | AE17: 0 | AF17: 0 | AG17: 0 | AH17: 0 | AI17: 1 | AJ17: 0 | AK17: 10 | AL17: 0 | AM17: 0 | AN17: 60 | AO17: 0 | AP17: 9 | AQ17: 61
A18: 16 | B18: G107441079ES | C18: Y | D18: 대전 | E18: 대덕구 | F18: 초등학교 | G18: 대전석봉초등학교 | H18: 1G | J18: O | K18: 2 | L18: 1 | M18: 1 | N18: 5 | O18: 3 | P18: 0 | Q18: 2 | R18: 1 | S18: 0 | T18: 0 | U18: 0 | V18: 0 | W18: 0 | X18: 0 | Y18: 0 | Z18: 0 | AA18: 0 | AB18: 0 | AC18: 6 | AD18: 3 | AE18: 0 | AF18: 0 | AG18: 0 | AH18: 0 | AI18: 1 | AJ18: 0 | AK18: 4 | AL18: 0 | AM18: 9 | AN18: 7 | AO18: 0 | AP18: 2 | AQ18: 18
A19: 17 | B19: G107430132HS | C19: Y | D19: 대전 | E19: 대덕구 | F19: 고등학교 | G19: 대전송촌고등학교 | H19: 1G | I19: 2.5G | J19: X | K19: 2 | L19: 3 | M19: 1 | N19: 14 | O19: 8 | P19: 0 | Q19: 15 | R19: 0 | S19: 0 | T19: 0 | U19: 1 | V19: 0 | W19: 0 | X19: 0 | Y19: 0 | Z19: 18 | AA19: 2 | AB19: 0 | AC19: 0 | AD19: 0 | AE19: 0 | AF19: 10 | AG19: 4 | AH19: 0 | AI19: 1 | AJ19: 0 | AK19: 11 | AL19: 0 | AM19: 0 | AN19: 53 | AO19: 0 | AP19: 10 | AQ19: 54
A20: 18 | B20: G107441022MS | C20: Y | D20: 대전 | E20: 대덕구 | F20: 중학교 | G20: 대전송촌중학교 | H20: 1G | I20: 2.5G | J20: X | K20: 2 | L20: 3 | M20: 1 | N20: 5 | O20: 3 | P20: 0 | Q20: 10 | R20: 4 | S20: 0 | T20: 3 | U20: 1 | V20: 0 | W20: 0 | X20: 0 | Y20: 0 | Z20: 11 | AA20: 5 | AB20: 0 | AC20: 0 | AD20: 0 | AE20: 0 | AF20: 0 | AG20: 0 | AH20: 0 | AI20: 1 | AJ20: 0 | AK20: 8 | AL20: 0 | AM20: 0 | AN20: 41 | AO20: 0 | AP20: 5 | AQ20: 44
A21: 19 | B21: G107441083ES | C21: Y | D21: 대전 | E21: 대덕구 | F21: 초등학교 | G21: 대전송촌초등학교 | H21: 1G | I21: 2.5G | J21: O | K21: 2 | L21: 0 | M21: 0 | N21: 11 | O21: 2 | P21: 1 | Q21: 1 | R21: 0 | S21: 0 | T21: 0 | U21: 0 | V21: 0 | W21: 0 | X21: 0 | Y21: 0 | Z21: 8 | AA21: 1 | AB21: 6 | AC21: 0 | AD21: 0 | AE21: 0 | AF21: 0 | AG21: 0 | AH21: 0 | AI21: 1 | AJ21: 0 | AK21: 6 | AL21: 0 | AM21: 33 | AN21: 15 | AO21: 0 | AP21: 2 | AQ21: 53
A22: 20 | B22: G107441086ES | C22: Y | D22: 대전 | E22: 대덕구 | F22: 초등학교 | G22: 대전양지초등학교 | H22: 1G | J22: O | K22: 2 | L22: 1 | M22: 1 | N22: 11 | O22: 4 | P22: 0 | Q22: 5 | R22: 0 | S22: 0 | T22: 0 | U22: 0 | V22: 0 | W22: 0 | X22: 0 | Y22: 0 | Z22: 15 | AA22: 3 | AB22: 0 | AC22: 0 | AD22: 0 | AE22: 0 | AF22: 0 | AG22: 0 | AH22: 0 | AI22: 1 | AJ22: 1 | AK22: 2 | AL22: 0 | AM22: 9 | AN22: 27 | AO22: 0 | AP22: 3 | AQ22: 36
A23: 21 | B23: G107430357VH | C23: Y | D23: 대전 | E23: 대덕구 | F23: 특수학교 | G23: 대전온라인학교 | H23: 1G | J23: X | K23: 2 | L23: 1 | M23: 1 | N23: 8 | O23: 2 | P23: 0 | Q23: 0 | R23: 0 | S23: 0 | T23: 0 | U23: 0 | V23: 0 | W23: 1 | X23: 0 | Y23: 0 | Z23: 6 | AA23: 1 | AB23: 0 | AC23: 0 | AD23: 0 | AE23: 0 | AF23: 0 | AG23: 0 | AH23: 0 | AI23: 1 | AJ23: 0 | AK23: 1 | AL23: 0 | AM23: 0 | AN23: 13 | AO23: 0 | AP23: 1 | AQ23: 13
A24: 22 | B24: G107441025MS | C24: Y | D24: 대전 | E24: 대덕구 | F24: 중학교 | G24: 대전용전중학교 | H24: 1G | J24: X | K24: 2 | L24: 2 | M24: 1 | N24: 4 | O24: 3 | P24: 0 | Q24: 13 | R24: 0 | S24: 0 | T24: 0 | U24: 0 | V24: 0 | W24: 0 | X24: 0 | Y24: 0 | Z24: 0 | AA24: 0 | AB24: 0 | AC24: 17 | AD24: 2 | AE24: 0 | AF24: 0 | AG24: 0 | AH24: 0 | AI24: 1 | AJ24: 0 | AK24: 8 | AL24: 0 | AM24: 0 | AN24: 39 | AO24: 0 | AP24: 7 | AQ24: 40
A25: 23 | B25: G107430113SS | C25: Y | D25: 대전 | E25: 대덕구 | F25: 특수학교 | G25: 대전원명학교 | H25: 1G | J25: X | K25: 2 | L25: 3 | M25: 1 | N25: 10 | O25: 1 | P25: 0 | Q25: 6 | R25: 0 | S25: 0 | T25: 2 | U25: 0 | V25: 0 | W25: 0 | X25: 0 | Y25: 0 | Z25: 14 | AA25: 0 | AB25: 0 | AC25: 0 | AD25: 0 | AE25: 0 | AF25: 0 | AG25: 0 | AH25: 0 | AI25: 1 | AJ25: 0 | AK25: 14 | AL25: 0 | AM25: 0 | AN25: 65 | AO25: 3 | AP25: 11 | AQ25: 65
A26: 24 | B26: G107430240HS | C26: Y | D26: 대전 | E26: 대덕구 | F26: 고등학교 | G26: 대전이문고등학교 | H26: 1G | J26: X | K26: 2 | L26: 2 | M26: 1 | N26: 7 | O26: 3 | P26: 0 | Q26: 6 | R26: 2 | S26: 0 | T26: 2 | U26: 3 | V26: 0 | W26: 0 | X26: 0 | Y26: 0 | Z26: 10 | AA26: 1 | AB26: 0 | AC26: 0 | AD26: 0 | AE26: 0 | AF26: 0 | AG26: 0 | AH26: 0 | AI26: 1 | AJ26: 0 | AK26: 11 | AL26: 0 | AM26: 0 | AN26: 64 | AO26: 0 | AP26: 10 | AQ26: 65
A27: 25 | B27: G107441095ES | C27: Y | D27: 대전 | E27: 대덕구 | F27: 초등학교 | G27: 대전중리초등학교 | H27: 1G | I27: 2.5G | J27: O | K27: 2 | L27: 1 | M27: 1 | N27: 6 | O27: 3 | P27: 0 | Q27: 10 | R27: 2 | S27: 0 | T27: 0 | U27: 0 | V27: 0 | W27: 0 | X27: 0 | Y27: 0 | Z27: 0 | AA27: 0 | AB27: 0 | AC27: 0 | AD27: 0 | AE27: 0 | AF27: 15 | AG27: 4 | AH27: 0 | AI27: 1 | AJ27: 0 | AK27: 6 | AL27: 0 | AM27: 23 | AN27: 27 | AO27: 0 | AP27: 5 | AQ27: 51
A28: 26 | B28: G107441097ES | C28: Y | D28: 대전 | E28: 대덕구 | F28: 초등학교 | G28: 대전중원초등학교 | H28: 1G | I28: 2.5G | J28: O | K28: 2 | L28: 0 | M28: 0 | N28: 9 | O28: 10 | P28: 1 | Q28: 0 | R28: 0 | S28: 0 | T28: 1 | U28: 0 | V28: 0 | W28: 0 | X28: 1 | Y28: 0 | Z28: 5 | AA28: 7 | AB28: 6 | AC28: 0 | AD28: 0 | AE28: 0 | AF28: 0 | AG28: 0 | AH28: 0 | AI28: 1 | AJ28: 0 | AK28: 8 | AL28: 1 | AM28: 26 | AN28: 26 | AO28: 2 | AP28: 4 | AQ28: 56
A29: 27 | B29: G107430349SS | C29: Y | D29: 대전 | E29: 대덕구 | F29: 특수학교 | G29: 대전해든학교 | H29: 1G | J29: X | K29: 2 | L29: 12 | M29: 11 | N29: 17 | O29: 10 | P29: 0 | Q29: 2 | R29: 1 | S29: 0 | T29: 0 | U29: 0 | V29: 0 | W29: 0 | X29: 0 | Y29: 0 | Z29: 18 | AA29: 10 | AB29: 0 | AC29: 0 | AD29: 0 | AE29: 0 | AF29: 0 | AG29: 0 | AH29: 0 | AI29: 1 | AJ29: 0 | AK29: 6 | AL29: 0 | AM29: 0 | AN29: 58 | AO29: 0 | AP29: 6 | AQ29: 58
A30: 28 | B30: G107441103ES | C30: Y | D30: 대전 | E30: 대덕구 | F30: 초등학교 | G30: 대전화정초등학교 | H30: 1G | J30: X | K30: 2 | L30: 1 | M30: 1 | N30: 8 | O30: 1 | P30: 0 | Q30: 13 | R30: 4 | S30: 0 | T30: 0 | U30: 0 | V30: 0 | W30: 0 | X30: 0 | Y30: 0 | Z30: 0 | AA30: 0 | AB30: 0 | AC30: 0 | AD30: 0 | AE30: 0 | AF30: 21 | AG30: 5 | AH30: 0 | AI30: 1 | AJ30: 1 | AK30: 6 | AL30: 0 | AM30: 13 | AN30: 25 | AO30: 0 | AP30: 6 | AQ30: 39
A31: 29 | B31: G107430039HS | C31: Y | D31: 대전 | E31: 대덕구 | F31: 고등학교 | G31: 동대전고등학교 | H31: 1G | I31: 2.5G | J31: X | K31: 2 | L31: 1 | M31: 1 | N31: 19 | O31: 4 | P31: 0 | Q31: 0 | R31: 0 | S31: 0 | T31: 0 | U31: 0 | V31: 0 | W31: 0 | X31: 0 | Y31: 0 | Z31: 18 | AA31: 3 | AB31: 0 | AC31: 0 | AD31: 0 | AE31: 0 | AF31: 0 | AG31: 0 | AH31: 0 | AI31: 1 | AJ31: 0 | AK31: 6 | AL31: 0 | AM31: 0 | AN31: 47 | AO31: 0 | AP31: 5 | AQ31: 48
A32: 30 | B32: G107441110ES | C32: Y | D32: 대전 | E32: 대덕구 | F32: 초등학교 | G32: 새일초등학교 | H32: 1G | J32: O | K32: 2 | L32: 1 | M32: 1 | N32: 7 | O32: 1 | P32: 0 | Q32: 2 | R32: 4 | S32: 0 | T32: 0 | U32: 0 | V32: 0 | W32: 0 | X32: 0 | Y32: 0 | Z32: 0 | AA32: 0 | AB32: 0 | AC32: 9 | AD32: 4 | AE32: 0 | AF32: 0 | AG32: 0 | AH32: 0 | AI32: 1 | AJ32: 0 | AK32: 11 | AL32: 0 | AM32: 19 | AN32: 19 | AO32: 0 | AP32: 7 | AQ32: 42
A33: 31 | B33: G107441036MS | C33: Y | D33: 대전 | E33: 대덕구 | F33: 중학교 | G33: 신탄중앙중학교 | H33: 1G | J33: X | K33: 2 | L33: 1 | M33: 1 | N33: 11 | O33: 3 | P33: 0 | Q33: 0 | R33: 0 | S33: 0 | T33: 0 | U33: 0 | V33: 0 | W33: 0 | X33: 0 | Y33: 0 | Z33: 10 | AA33: 2 | AB33: 0 | AC33: 0 | AD33: 0 | AE33: 0 | AF33: 0 | AG33: 0 | AH33: 0 | AI33: 1 | AJ33: 0 | AK33: 5 | AL33: 0 | AM33: 0 | AN33: 27 | AO33: 0 | AP33: 4 | AQ33: 28
A34: 32 | B34: G107430041HS | C34: Y | D34: 대전 | E34: 대덕구 | F34: 고등학교 | G34: 신탄진고등학교 | H34: 1G | J34: O | K34: 2 | L34: 1 | M34: 1 | N34: 11 | O34: 5 | P34: 0 | Q34: 3 | R34: 3 | S34: 0 | T34: 0 | U34: 0 | V34: 0 | W34: 0 | X34: 0 | Y34: 0 | Z34: 0 | AA34: 0 | AB34: 0 | AC34: 13 | AD34: 7 | AE34: 0 | AF34: 0 | AG34: 0 | AH34: 0 | AI34: 1 | AJ34: 0 | AK34: 5 | AL34: 0 | AM34: 0 | AN34: 43 | AO34: 0 | AP34: 5 | AQ34: 43
A35: 33 | B35: G107441113ES | C35: Y | D35: 대전 | E35: 대덕구 | F35: 초등학교 | G35: 신탄진용정초등학교 | H35: 1G | I35: 2.5G | J35: X | K35: 2 | L35: 1 | M35: 1 | N35: 10 | O35: 3 | P35: 0 | Q35: 0 | R35: 0 | S35: 0 | T35: 1 | U35: 1 | V35: 0 | W35: 0 | X35: 0 | Y35: 0 | Z35: 5 | AA35: 0 | AB35: 0 | AC35: 0 | AD35: 0 | AE35: 0 | AF35: 4 | AG35: 1 | AH35: 0 | AI35: 1 | AJ35: 0 | AK35: 6 | AL35: 0 | AM35: 14 | AN35: 20 | AO35: 2 | AP35: 3 | AQ35: 35
A36: 34 | B36: G107441037MS | C36: Y | D36: 대전 | E36: 대덕구 | F36: 중학교 | G36: 신탄진중학교 | H36: 1G | J36: X | K36: 2 | L36: 3 | M36: 1 | N36: 21 | O36: 3 | P36: 0 | Q36: 3 | R36: 0 | S36: 0 | T36: 0 | U36: 0 | V36: 0 | W36: 1 | X36: 0 | Y36: 0 | Z36: 23 | AA36: 2 | AB36: 0 | AC36: 0 | AD36: 0 | AE36: 0 | AF36: 0 | AG36: 0 | AH36: 0 | AI36: 1 | AJ36: 0 | AK36: 7 | AL36: 0 | AM36: 0 | AN36: 29 | AO36: 0 | AP36: 3 | AQ36: 30
A37: 35 | B37: G107441114ES | C37: Y | D37: 대전 | E37: 대덕구 | F37: 초등학교 | G37: 신탄진초등학교 | H37: 1G | J37: X | K37: 2 | L37: 2 | M37: 2 | N37: 14 | O37: 1 | P37: 0 | Q37: 18 | R37: 3 | S37: 0 | T37: 0 | U37: 0 | V37: 0 | W37: 0 | X37: 0 | Y37: 0 | Z37: 31 | AA37: 3 | AB37: 0 | AC37: 0 | AD37: 0 | AE37: 0 | AF37: 0 | AG37: 0 | AH37: 0 | AI37: 1 | AJ37: 2 | AK37: 11 | AL37: 0 | AM37: 5 | AN37: 48 | AO37: 0 | AP37: 5 | AQ37: 57
A38: 36 | B38: G107441038MS | C38: Y | D38: 대전 | E38: 대덕구 | F38: 중학교 | G38: 오정중학교 | H38: 1G | J38: X | K38: 2 | L38: 1 | M38: 1 | N38: 9 | O38: 2 | P38: 2 | Q38: 11 | R38: 3 | S38: 1 | T38: 0 | U38: 0 | V38: 0 | W38: 0 | X38: 0 | Y38: 0 | Z38: 0 | AA38: 0 | AB38: 0 | AC38: 18 | AD38: 4 | AE38: 6 | AF38: 0 | AG38: 0 | AH38: 0 | AI38: 1 | AJ38: 0 | AK38: 6 | AL38: 0 | AM38: 0 | AN38: 20 | AO38: 0 | AP38: 5 | AQ38: 20
A39: 37 | B39: G107441115ES | C39: Y | D39: 대전 | E39: 대덕구 | F39: 초등학교 | G39: 와동초등학교 | H39: 1G | J39: O | K39: 2 | L39: 0 | M39: 0 | N39: 9 | O39: 1 | P39: 1 | Q39: 1 | R39: 0 | S39: 0 | T39: 0 | U39: 0 | V39: 0 | W39: 0 | X39: 0 | Y39: 0 | Z39: 0 | AA39: 0 | AB39: 0 | AC39: 0 | AD39: 0 | AE39: 0 | AF39: 8 | AG39: 1 | AH39: 3 | AI39: 1 | AJ39: 0 | AK39: 6 | AL39: 0 | AM39: 14 | AN39: 13 | AO39: 0 | AP39: 3 | AQ39: 30
A40: 38 | B40: G107441116ES | C40: Y | D40: 대전 | E40: 대덕구 | F40: 초등학교 | G40: 장동초등학교 | H40: 1G | J40: X | K40: 2 | L40: 1 | M40: 1 | N40: 6 | O40: 1 | P40: 0 | Q40: 3 | R40: 2 | S40: 0 | T40: 0 | U40: 0 | V40: 0 | W40: 0 | X40: 0 | Y40: 0 | Z40: 8 | AA40: 2 | AB40: 0 | AC40: 0 | AD40: 0 | AE40: 0 | AF40: 0 | AG40: 0 | AH40: 0 | AI40: 1 | AJ40: 1 | AK40: 2 | AL40: 0 | AM40: 2 | AN40: 11 | AO40: 0 | AP40: 2 | AQ40: 14
...

Sheet 0.학교(충남+대전)
D1: 대상학교수 | AR1: SWIMS연동 AP 수량
E2: Y/N | AE2: 411 진단Data 작업 | AI2: 자산구성파일 개수 | AR2: 제조사 | AS2: H1Radio | AU2: MERCURY | AV2: 가온브로드밴드 | AX2: 다보링크 | BA2: 엘텍 | BB2: 다산네트웍스
B3: 기존 순서 | C3: 학교코드 | D3: 정보공시코드 | E3: 발행 | F3: 교육청 | G3: 지역 | H3: 학교유형 | I3: 학교명 | J3: 주소 | K3: 설립연도 | L3: 담당 선생님 이름 | M3: 담당 선생님 업무 | N3: 설문 담당자 이름 | O3: 직통 연락처 | P3: 이메일 | Q3: 건물수 | R3: 교실수 (특수) | S3: 교무 (연구)/ 행정실수 | T3: 학급수 (특수) | U3: 교직원수 | V3: 학생수 | W3: 컴퓨터실 수 | X3: 망분리 여부 | Y3: 스쿨넷 회선속도 | Z3: 스쿨넷 회선속도 | AA3: 무선망 전용 회선속도 | AB3: 10G 청약 여부 | AC3: SWIMS 연동 AP 수량 | AD3: 학교 자체 AP 수량 | AE3: 교육청AP수량 | AF3: 자체 AP 수량 | AG3: 교육청 PoE 수량 | AH3: 자체 PoE 수량 | AI3: AP 가상자산 | AJ3: PoE 가상자산 | AK3: 보안장비 가상자산 | AL3: Switch 가상자산 | AO3: 특성 | AP3: 학교 특이사항 | AQ3: 일괄업로드 특이사항 | AR3: 모델명 / 합계 | AS3: AR-WF6E-2564I | AT3: H1-A7114N | AU3: MCAP-704SM | AV3: EAP2244 | AW3: EAP2245 | AX3: DVW604 | AY3: DVW624 | AZ3: DVW704 | BA3: H834AX-P | BB3: W340 | BC3: 분류1 | BD3: 분류2 | BE3: 분류3
B4: 94 | C4: N108140237HS | D4: S120002546 | E4: Y | F4: 충남 | G4: 계룡 | H4: 고등학교 | I4: 계룡고등학교 | J4: 충남 계룡시 두마면 서금암로 89 | K4: 38833 | L4: 김대성 | M4: 정보 | N4: 김대성 | O4: 042-840-5314 | P4: kimds0316@naver.com | Q4: 2 | R4: 27(6) | S4: 9 | T4: 22(1) | U4: 57 | V4: 578(8) | W4: 1 | Y4: 1G | Z4: 1G | AB4: X | AC4: 39 | AD4: =AF4 -> 0 | AE4: 39 | AF4: 0 | AG4: 8 | AH4: 0 | AI4: 39 | AJ4: 8 | AK4: 2 | AL4: 25 | AR4: =SUM(AS4:BB4) -> 39 | AS4: 0 | AT4: 0 | AU4: 0 | AV4: 4 | AW4: 2 | AX4: 24 | AY4: 0 | AZ4: 0 | BA4: 0 | BB4: 9 | BC4: 집선스위치>>스쿨넷회선 구간 측정
B5: 530 | C5: N108222124ES | D5: S120002976 | E5: N | F5: 충남 | G5: 계룡 | H5: 초등학교 | I5: 계룡대실초등학교 | J5: 충남 계룡시 두마면 대실남북로 113 | K5: 45717 | L5: 조창희 | M5: 정보 | N5: 조창희 | O5: 042-710-4701 | P5: gomtingjo@naver.com | Q5: 2 | R5: 38(7) | S5: 11 | T5: 22(1) | U5: 32 | V5: 441(4) | W5: 1 | Y5: 1G | Z5: 1G | AB5: X | AC5: 73 | AD5: =AF5 -> 0 | AE5: 0 | AF5: 0 | AG5: 0 | AH5: 0 | AI5: 0 | AJ5: 0 | AK5: 0 | AL5: 0 | AO5: 1 | AP5: 진단업무제외/신설학교 | AQ5: 1 | AR5: =SUM(AS5:BB5) -> 73 | AS5: 0 | AT5: 0 | AU5: 0 | AV5: 0 | AW5: 73 | AX5: 0 | AY5: 0 | AZ5: 0 | BA5: 0 | BB5: 0
B6: 529 | C6: N108222119MS | D6: S120002545 | E6: Y | F6: 충남 | G6: 계룡 | H6: 중학교 | I6: 계룡중학교 | J6: 충남 계룡시 서금암 5길 17 | K6: 38777 | L6: 양현원 | M6: 정보 | Q6: 2 | R6: 34(6) | S6: 15 | T6: 28(2) | U6: 59 | V6: 659(8) | W6: 1 | Y6: 60M | Z6: 60M | AA6: 2.5G | AB6: O | AC6: 34 | AD6: =AF6 -> 0 | AE6: 30 | AF6: 0 | AG6: 6 | AH6: 0 | AI6: 30 | AJ6: 6 | AK6: 3 | AL6: 19 | AR6: =SUM(AS6:BB6) -> 34 | AS6: 0 | AT6: 0 | AU6: 0 | AV6: 0 | AW6: 1 | AX6: 29 | AY6: 3 | AZ6: 0 | BA6: 0 | BB6: 1 | BC6: 집선스위치>>무선인터넷회선 구간 측정
B7: 527 | C7: N108222061ES | E7: Y | F7: 충남 | G7: 계룡 | H7: 초등학교 | I7: 금암초등학교 | J7: 충남 계룡시 장안로 104 | K7: 38777 | L7: 문숙 | M7: 정보 | N7: 문숙 | O7: 042-841-0872 | P7: swani3@hanmail.net | Q7: 10 | R7: 22(3) | S7: 7 | T7: 18(1) | U7: 49 | V7: 365(10) | W7: 1 | Y7: 1G | Z7: 1G | AA7: 2.5G | AB7: O | AC7: 29 | AD7: =AF7 -> 0 | AE7: 25 | AF7: 0 | AG7: 6 | AH7: 0 | AI7: 25 | AJ7: 6 | AK7: 3 | AL7: 24 | AR7: =SUM(AS7:BB7) -> 29 | AS7: 0 | AT7: 4 | AU7: 0 | AV7: 0 | AW7: 4 | AX7: 2 | AY7: 15 | AZ7: 0 | BA7: 0 | BB7: 4 | BC7: 집선스위치>>무선인터넷회선 구간 측정
B8: 507 | C8: N108222036ES | D8: S120000459 | E8: Y | F8: 충남 | G8: 계룡 | H8: 초등학교 | I8: 두마초등학교 | J8: 충남 계룡시 두마면 팥거리로 160 | K8: 8553 | N8: 유보현 | O8: 010-3813-3682 | P8: topfgfl@naver.com | Q8: 8 | R8: 28(5) | S8: 6 | T8: 19(2) | U8: 31 | V8: 331(8) | W8: 1 | Y8: 1G | Z8: 1G | AA8: 2.5G | AB8: O | AC8: 33 | AD8: =AF8 -> 0 | AE8: 33 | AF8: 0 | AG8: 7 | AH8: 0 | AI8: 33 | AJ8: 7 | AK8: 3 | AL8: 17 | AR8: =SUM(AS8:BB8) -> 33 | AS8: 0 | AT8: 0 | AU8: 0 | AV8: 0 | AW8: 0 | AX8: 23 | AY8: 1 | AZ8: 0 | BA8: 0 | BB8: 9 | BC8: 집선스위치>>무선인터넷회선 구간 측정
B9: 492 | C9: N108222019ES | D9: S120002529 | E9: Y | F9: 충남 | G9: 계룡 | H9: 초등학교 | I9: 신도초등학교 | J9: 충남 계룡시 엄사면 번영3길 82 | K9: 38412 | L9: 최수현 | M9: 정보 | N9: 최수현 | O9: 042-841-9860 | P9: dhw1105@korea.kr | Q9: 3 | R9: 31(6) | S9: 11 | T9: 18(3) | U9: 28 | V9: 320(13) | W9: 1 | Y9: 60M | Z9: 60M | AA9: 2.5G | AB9: O | AC9: 29 | AD9: =AF9 -> 0 | AE9: 26 | AF9: 0 | AG9: 9 | AH9: 0 | AI9: 26 | AJ9: 9 | AK9: 3 | AL9: 14 | AR9: =SUM(AS9:BB9) -> 29 | AS9: 0 | AT9: 0 | AU9: 0 | AV9: 3 | AW9: 1 | AX9: 11 | AY9: 3 | AZ9: 0 | BA9: 0 | BB9: 11 | BC9: 집선스위치>>무선인터넷회선 구간 측정
B10: 490 | C10: N108222017MS | D10: S120000434 | E10: Y | F10: 충남 | G10: 계룡 | H10: 중학교 | I10: 엄사중학교 | J10: 충남 계룡시 엄사면 번영11길3 | K10: 36586 | N10: 김경애 | O10: 042-841-9676 | Q10: 2 | R10: 26(5) | S10: 17 | T10: 20(1) | U10: 49 | V10: 511(6) | W10: 1 | Y10: 1G | Z10: 1G | AA10: 2.5G | AB10: O | AC10: 41 | AD10: =AF10 -> 0 | AE10: 38 | AF10: 0 | AG10: 8 | AH10: 0 | AI10: 38 | AJ10: 8 | AK10: 3 | AL10: 15 | AR10: =SUM(AS10:BB10) -> 41 | AS10: 0 | AT10: 0 | AU10: 0 | AV10: 0 | AW10: 1 | AX10: 32 | AY10: 3 | AZ10: 0 | BA10: 0 | BB10: 5 | BC10: 집선스위치>>무선인터넷회선 구간 측정
B11: 516 | C11: N108222046ES | D11: S120000479 | E11: Y | F11: 충남 | G11: 계룡 | H11: 초등학교 | I11: 엄사초등학교 | J11: 충남 계룡시 엄사면 번영3길 30 | K11: 34947 | N11: 조석근 | O11: 042 841 4497 | P11: xkskxhshxm57@naver.com | Q11: 4 | R11: 22(5) | S11: 11 | T11: 17(1) | U11: 25 | V11: 301(4) | W11: 1 | Y11: 1G | Z11: 1G | AB11: X | AC11: 30 | AD11: =AF11 -> 0 | AE11: 30 | AF11: 0 | AG11: 10 | AH11: 0 | AI11: 30 | AJ11: 10 | AK11: 2 | AL11: 12 | AR11: =SUM(AS11:BB11) -> 30 | AS11: 0 | AT11: 0 | AU11: 0 | AV11: 0 | AW11: 0 | AX11: 25 | AY11: 1 | AZ11: 0 | BA11: 0 | BB11: 4 | BC11: 집선스위치>>스쿨넷회선 구간 측정
B12: 28 | C12: N108140063HS | D12: S120000218 | E12: Y | F12: 충남 | G12: 계룡 | H12: 고등학교 | I12: 용남고등학교 | J12: 충남 계룡시 신도안면 신도안1길 32 | K12: 33306 | L12: 정일영 | M12: 정보 | N12: 정일영 | O12: 042-717-2160 | Q12: 4 | R12: 40(9) | S12: 18 | T12: 31(1) | U12: 76 | V12: 817(6) | W12: 1 | Y12: 1G | Z12: 1G | AA12: 2.5G | AB12: O | AC12: 54 | AD12: =AF12 -> 0 | AE12: 54 | AF12: 0 | AG12: 6 | AH12: 0 | AI12: 54 | AJ12: 6 | AK12: 3 | AL12: 15 | AR12: =SUM(AS12:BB12) -> 54 | AS12: 0 | AT12: 0 | AU12: 0 | AV12: 4 | AW12: 4 | AX12: 46 | AY12: 0 | AZ12: 0 | BA12: 0 | BB12: 0 | BC12: 집선스위치>>무선인터넷회선 구간 측정
B13: 486 | C13: N108222012MS | D13: S120000439 | E13: Y | F13: 충남 | G13: 계룡 | H13: 중학교 | I13: 용남중학교 | J13: 충남 계룡시 신도안면 신도안2길 66 | K13: 32752 | L13: 이정재 | M13: 정보 | N13: 이정재 | O13: 042-551-1501 | P13: pisicc00@ai.cne.go.kr | Q13: 4 | R13: 29(4) | S13: 13 | T13: 23(1) | U13: 55 | V13: 605(3) | W13: 1 | Y13: 1G | Z13: 1G | AA13: 2.5G | AB13: O | AC13: 35 | AD13: =AF13 -> 0 | AE13: 32 | AF13: 0 | AG13: 7 | AH13: 0 | AI13: 32 | AJ13: 7 | AK13: 3 | AL13: 13 | AR13: =SUM(AS13:BB13) -> 35 | AS13: 0 | AT13: 0 | AU13: 0 | AV13: 0 | AW13: 1 | AX13: 0 | AY13: 3 | AZ13: 0 | BA13: 0 | BB13: 31 | BC13: 집선스위치>>무선인터넷회선 구간 측정
B14: 521 | C14: N108222051ES | E14: Y | F14: 충남 | G14: 계룡 | H14: 초등학교 | I14: 용남초등학교 | J14: 충남 계룡시 신도안면 신도안1길 88 | K14: 32758 | N14: 김수진 | O14: 042-551-1504 | P14: tnwls284566@naver.com | Q14: 4 | R14: 48(5) | S14: 5 | T14: 39(1) | U14: 83 | V14: 906(4) | W14: 2 | Y14: 1G | Z14: 1G | AA14: 2.5G | AB14: O | AC14: 51 | AD14: =AF14 -> 0 | AE14: 44 | AF14: 0 | AG14: 6 | AH14: 0 | AI14: 44 | AJ14: 6 | AK14: 3 | AL14: 19 | AR14: =SUM(AS14:BB14) -> 51 | AS14: 0 | AT14: 2 | AU14: 0 | AV14: 0 | AW14: 3 | AX14: 41 | AY14: 4 | AZ14: 0 | BA14: 0 | BB14: 1 | BC14: 집선스위치>>무선인터넷회선 구간 측정
B15: 258 | C15: N108161016MS | D15: S120000277 | E15: Y | F15: 충남 | G15: 공주 | H15: 중학교 | I15: 경천중학교 | J15: 충남 공주시 계룡면 어사길2 | K15: 25490 | L15: 조은아 | M15: 정보 | N15: 조은아 | O15: 041-852-4043 | P15: jea168@naver.com | Q15: 2 | R15: 8(5) | S15: 3 | T15: 3(0) | U15: 9 | V15: 32(0) | W15: 1 | Y15: 60M | Z15: 60M | AB15: X | AC15: 8 | AD15: =AF15 -> 0 | AE15: 9 | AF15: 0 | AG15: 4 | AH15: 0 | AI15: 9 | AJ15: 4 | AK15: 2 | AL15: 16 | AQ15: 0 | AR15: =SUM(AS15:BB15) -> 8 | AS15: 0 | AT15: 2 | AU15: 0 | AV15: 0 | AW15: 0 | AX15: 4 | AY15: 2 | AZ15: 0 | BA15: 0 | BB15: 0 | BC15: 집선스위치>>스쿨넷회선 구간 측정
B16: 262 | C16: N108161021ES | D16: S120000293 | E16: Y | F16: 충남 | G16: 공주 | H16: 초등학교 | I16: 경천초등학교 | J16: 충남 공주시 계룡면 신원사로112 | K16: 16577 | L16: 김채원 | M16: 정보 | N16: 김채원 | O16: 010-6402-3568 | P16: 1234567na@naver.com | Q16: 2 | R16: 9(3) | S16: 5 | T16: 6(0) | U16: 11 | V16: 14(0) | Y16: 60M | Z16: 60M | AB16: X | AC16: 12 | AD16: =AF16 -> 0 | AE16: 6 | AF16: 0 | AG16: 1 | AH16: 0 | AI16: 8 | AJ16: 2 | AK16: 2 | AL16: 26 | AQ16: 0 | AR16: =SUM(AS16:BB16) -> 12 | AS16: 0 | AT16: 0 | AU16: 0 | AV16: 0 | AW16: 0 | AX16: 0 | AY16: 8 | AZ16: 0 | BA16: 0 | BB16: 4 | BC16: 집선스위치>>스쿨넷회선 구간 측정
B17: 263 | C17: N108161022ES | D17: S120000294 | E17: Y | F17: 충남 | G17: 공주 | H17: 초등학교 | I17: 계룡초등학교 | J17: 충남 공주시 계룡면 영규대사로 459 | K17: 7108 | N17: 노유림 | O17: 041-857-5023 | P17: dbfla802@naver.com | Q17: 3 | R17: 11(5) | S17: 6 | T17: 6(0) | U17: 18 | V17: 40(0) | W17: 2 | Y17: 60M | Z17: 60M | AB17: X | AC17: 10 | AD17: =AF17 -> 0 | AE17: 10 | AF17: 0 | AG17: 4 | AH17: 0 | AI17: 11 | AJ17: 4 | AK17: 2 | AL17: 19 | AQ17: 0 | AR17: =SUM(AS17:BB17) -> 10 | AS17: 0 | AT17: 0 | AU17: 0 | AV17: 0 | AW17: 0 | AX17: 8 | AY17: 1 | AZ17: 0 | BA17: 0 | BB17: 1 | BC17: 집선스위치>>스쿨넷회선 구간 측정
B18: 4 | C18: N108140036HS | D18: S120000131 | E18: Y | F18: 충남 | G18: 공주 | H18: 고등학교 | I18: 공주고등학교 | J18: 충남 공주시 공주고담길 2 | K18: 8167 | N18: 팽주현 | O18: 041-855-1705 | P18: phlox898@gmail.com | Q18: 7 | R18: 41(14) | S18: 22 | T18: 25(1) | U18: 65 | V18: 491(4) | W18: 1 | Y18: 1G | Z18: 1G | AB18: X | AC18: 53 | AD18: =AF18 -> 0 | AE18: 41 | AF18: 0 | AG18: 7 | AH18: 0 | AI18: 41 | AJ18: 7 | AK18: 2 | AL18: 29 | AQ18: 0 | AR18: =SUM(AS18:BB18) -> 53 | AS18: 0 | AT18: 0 | AU18: 0 | AV18: 1 | AW18: 0 | AX18: 30 | AY18: 9 | AZ18: 0 | BA18: 0 | BB18: 13 | BC18: 집선스위치>>스쿨넷회선 구간 측정
B19: 264 | C19: N108161023ES | D19: S120000295 | E19: Y | F19: 충남 | G19: 공주 | H19: 초등학교 | I19: 공주교동초등학교 | J19: 충남 공주시 용당길 69-6 | K19: 24523 | L19: 윤송원 | M19: 정보 | N19: 윤송원 | O19: 010-8651-2480 | P19: hobbang305@naver.com | Q19: 2 | R19: 10(1) | S19: 6 | T19: 8(1) | U19: 15 | V19: 120(5) | W19: 1 | Y19: 1G | Z19: 1G | AB19: X | AC19: 31 | AD19: =AF19 -> 0 | AE19: 25 | AF19: 0 | AG19: 8 | AH19: 0 | AI19: 25 | AJ19: 8 | AK19: 2 | AL19: 14 | AQ19: 0 | AR19: =SUM(AS19:BB19) -> 31 | AS19: 0 | AT19: 9 | AU19: 0 | AV19: 0 | AW19: 0 | AX19: 21 | AY19: 1 | AZ19: 0 | BA19: 0 | BB19: 0 | BC19: 집선스위치>>스쿨넷회선 구간 측정
B20: 1 | C20: N107004442ES | D20: S000003499 | E20: Y | F20: 충남 | G20: 공주 | H20: 초등학교 | I20: 공주교육대학교부설초등학교 | J20: 충남 공주시 하선길 47 | K20: 13993 | Q20: 4 | R20: 36(11) | S20: 7 | T20: 25(1) | U20: 33 | V20: 469(6) | Y20: 1G | Z20: 1G | AB20: X | AC20: 0 | AD20: =AF20 -> 69 | AE20: 0 | AF20: 69 | AG20: 0 | AH20: 7 | AI20: 69 | AJ20: 7 | AK20: 2 | AL20: 16 | AQ20: 0 | AR20: =SUM(AS20:BB20) -> 0 | AS20: 0 | AT20: 0 | AU20: 0 | AV20: 0 | AW20: 0 | AX20: 0 | AY20: 0 | AZ20: 0 | BA20: 0 | BB20: 0 | BC20: 집선스위치>>스쿨넷회선 구간 측정
B21: 38 | C21: N108140080HS | D21: S120000133 | E21: Y | F21: 충남 | G21: 공주 | H21: 고등학교 | I21: 공주금성여자고등학교 | J21: 충남 공주시 무령로 103 | K21: 29285 | L21: 김동규 | M21: 정보 | N21: 김동규 | O21: 041-8546811 | P21: dongkyu7530@naver.com | Q21: 5 | R21: 31(10) | S21: 27 | T21: 21(0) | U21: 44 | V21: 390(0) | W21: 1 | Y21: 1G | Z21: 1G | AB21: X | AC21: 36 | AD21: =AF21 -> 0 | AE21: 35 | AF21: 0 | AG21: 11 | AH21: 0 | AI21: 35 | AJ21: 11 | AK21: 2 | AL21: 23 | AQ21: 0 | AR21: =SUM(AS21:BB21) -> 36 | AS21: 0 | AT21: 0 | AU21: 0 | AV21: 0 | AW21: 0 | AX21: 27 | AY21: 0 | AZ21: 0 | BA21: 0 | BB21: 9 | BC21: 집선스위치>>스쿨넷회선 구간 측정
B22: 265 | C22: N108161024ES | D22: S120000296 | E22: Y | F22: 충남 | G22: 공주 | H22: 초등학교 | I22: 공주금학초등학교 | J22: 충남 공주시 공주고담길 19 | K22: 14758 | Q22: 3 | R22: 9(2) | S22: 8 | T22: 7(1) | U22: 12 | V22: 47(4) | W22: 1 | Y22: 60M | Z22: 60M | AB22: X | AC22: 13 | AD22: =AF22 -> 0 | AE22: 13 | AF22: 0 | AG22: 4 | AH22: 0 | AI22: 15 | AJ22: 4 | AK22: 2 | AL22: 9 | AQ22: 0 | AR22: =SUM(AS22:BB22) -> 13 | AS22: 0 | AT22: 0 | AU22: 0 | AV22: 0 | AW22: 0 | AX22: 6 | AY22: 0 | AZ22: 0 | BA22: 0 | BB22: 7 | BC22: 집선스위치>>스쿨넷회선 구간 측정
B23: 112 | C23: N108140347HS | D23: S120000132 | E23: Y | F23: 충남 | G23: 공주 | H23: 고등학교 | I23: 공주마이스터고등학교 | J23: 충남 공주시 유구읍 중앙1길 27-12 | K23: 26372 | L23: 박진수 | M23: 정보 | N23: 박진수 | O23: 041-840-1441 | P23: pjs8674@naver.com | Q23: 5 | R23: 35(22) | S23: 12 | T23: 13(1) | U23: 38 | V23: 190(2) | Y23: 1G | Z23: 1G | AB23: X | AC23: 42 | AD23: =AF23 -> 0 | AE23: 37 | AF23: 0 | AG23: 12 | AH23: 0 | AI23: 37 | AJ23: 12 | AK23: 2 | AL23: 71 | AQ23: 0 | AR23: =SUM(AS23:BB23) -> 42 | AS23: 0 | AT23: 0 | AU23: 0 | AV23: 3 | AW23: 0 | AX23: 17 | AY23: 8 | AZ23: 0 | BA23: 0 | BB23: 14 | BC23: 집선스위치>>스쿨넷회선 구간 측정
B24: 266 | C24: N108161025ES | D24: S120000297 | E24: Y | F24: 충남 | G24: 공주 | H24: 초등학교 | I24: 공주봉황초등학교 | J24: 충남 공주시 오거리길5 | K24: 16735 | L24: 황순기 | M24: 정보 | N24: 황순기 | O24: 041-854-2203 | P24: skee0079@naver.com | Q24: 3 | R24: 12(5) | S24: 6 | T24: 7(1) | U24: 12 | V24: 73(4) | W24: 1 | Y24: 60M | Z24: 60M | AB24: X | AC24: 10 | AD24: =AF24 -> 0 | AE24: 10 | AF24: 0 | AG24: 3 | AH24: 0 | AI24: 10 | AJ24: 3 | AK24: 2 | AL24: 9 | AQ24: 0 | AR24: =SUM(AS24:BB24) -> 10 | AS24: 0 | AT24: 0 | AU24: 0 | AV24: 0 | AW24: 0 | AX24: 2 | AY24: 7 | AZ24: 0 | BA24: 0 | BB24: 1 | BC24: 집선스위치>>스쿨넷회선 구간 측정
B25: 259 | C25: N108161017MS | D25: S120000278 | E25: Y | F25: 충남 | G25: 공주 | H25: 중학교 | I25: 공주북중학교 | J25: 충남 공주시 제민천1길 113 | K25: 24819 | N25: 강용석 | O25: 041-854-3962 | P25: artman7@hanmail.net | Q25: 3 | R25: 12(3) | S25: 7 | T25: 9(0) | U25: 19 | V25: 214(0) | W25: 1 | Y25: 1G | Z25: 1G | AB25: X | AC25: 16 | AD25: =AF25 -> 0 | AE25: 16 | AF25: 0 | AG25: 5 | AH25: 0 | AI25: 16 | AJ25: 5 | AK25: 2 | AL25: 11 | AQ25: 0 | AR25: =SUM(AS25:BB25) -> 16 | AS25: 0 | AT25: 12 | AU25: 0 | AV25: 0 | AW25: 0 | AX25: 0 | AY25: 4 | AZ25: 0 | BA25: 0 | BB25: 0 | BC25: 집선스위치>>스쿨넷회선 구간 측정
B26: 95 | C26: N108140238HS | D26: S120000134 | E26: Y | F26: 충남 | G26: 공주 | H26: 고등학교 | I26: 공주생명과학고등학교 | J26: 충남 공주시 금벽로 317 | K26: 12126 | L26: 송민주 | M26: 정보 | N26: 송민주 | O26: 041-858-3500(3503~6) | P26: belle0037@naver.com | Q26: 18 | R26: 56(25) | S26: 9 | T26: 18(3) | U26: 45 | V26: 259(18) | W26: 2 | Y26: 1G | Z26: 1G | AB26: X | AC26: 55 | AD26: =AF26 -> 0 | AE26: 53 | AF26: 0 | AG26: 20 | AH26: 0 | AI26: 53 | AJ26: 20 | AK26: 2 | AL26: 40 | AQ26: 0 | AR26: =SUM(AS26:BB26) -> 55 | AS26: 0 | AT26: 0 | AU26: 0 | AV26: 1 | AW26: 0 | AX26: 54 | AY26: 0 | AZ26: 0 | BA26: 0 | BB26: 0 | BC26: 집선스위치>>스쿨넷회선 구간 측정
B27: 261 | C27: N108161020ES | D27: S120000298 | E27: Y | F27: 충남 | G27: 공주 | H27: 초등학교 | I27: 공주신월초등학교 | J27: 충남 공주시 번영1로 193 | K27: 37408 | N27: 신문수 | O27: 0418815013 | P27: tlstnans@cne.go.kr | Q27: 3 | R27: 52(8) | S27: 3 | T27: 45(2) | U27: 72 | V27: 1075(10) | W27: 2 | Y27: 1G | Z27: 1G | AA27: 2.5G | AB27: O | AC27: 59 | AD27: =AF27 -> 0 | AE27: 59 | AF27: 0 | AG27: 10 | AH27: 0 | AI27: 59 | AJ27: 10 | AK27: 3 | AL27: 38 | AQ27: 0 | AR27: =SUM(AS27:BB27) -> 59 | AS27: 0 | AT27: 0 | AU27: 0 | AV27: 0 | AW27: 0 | AX27: 46 | AY27: 5 | AZ27: 0 | BA27: 0 | BB27: 8 | BC27: 집선스위치>>무선인터넷회선 구간 측정
B28: 5 | C28: N108140037HS | D28: S120000135 | E28: Y | F28: 충남 | G28: 공주 | H28: 고등학교 | I28: 공주여자고등학교 | J28: 충남 공주시 공주여고길 14-1 | K28: 10349 | Q28: 5 | R28: 40(18) | S28: 13 | T28: 22(1) | U28: 56 | V28: 407(5) | W28: 1 | Y28: 1G | Z28: 1G | AB28: X | AC28: 35 | AD28: =AF28 -> 0 | AE28: 35 | AF28: 0 | AG28: 11 | AH28: 0 | AI28: 35 | AJ28: 11 | AK28: 2 | AL28: 24 | AQ28: 0 | AR28: =SUM(AS28:BB28) -> 35 | AS28: 0 | AT28: 0 | AU28: 0 | AV28: 0 | AW28: 0 | AX28: 28 | AY28: 2 | AZ28: 0 | BA28: 0 | BB28: 5 | BC28: 집선스위치>>스쿨넷회선 구간 측정
B29: 248 | C29: N108161005MS | D29: S120000279 | E29: Y | F29: 충남 | G29: 공주 | H29: 중학교 | I29: 공주여자중학교 | J29: 충남 공주시 용당길 54 | K29: 10349 | L29: 민선주 | M29: 정보 | N29: 민선주 | O29: 041-851-1001 | P29: miracle@ai.cne.go.kr | Q29: 3 | R29: 28(10) | S29: 13 | T29: 22(1) | U29: 51 | V29: 549(3) | W29: 1 | Y29: 1G | Z29: 1G | AA29: 2.5G | AB29: O | AC29: 35 | AD29: =AF29 -> 0 | AE29: 35 | AF29: 0 | AG29: 6 | AH29: 0 | AI29: 35 | AJ29: 6 | AK29: 3 | AL29: 26 | AQ29: 0 | AR29: =SUM(AS29:BB29) -> 35 | AS29: 0 | AT29: 0 | AU29: 0 | AV29: 0 | AW29: 0 | AX29: 22 | AY29: 4 | AZ29: 0 | BA29: 0 | BB29: 9 | BC29: 집선스위치>>무선인터넷회선 구간 측정
B30: 39 | C30: N108140082HS | D30: S120000137 | E30: Y | F30: 충남 | G30: 공주 | H30: 고등학교 | I30: 공주영명고등학교 | J30: 충남 공주시 중동 영명학당2길 33 | K30: 2480 | L30: 홍록기 | M30: 정보 | N30: 홍록기 | O30: 041-854-3382 | P30: lokki@hanmail.net | Q30: 5 | R30: 37(13) | S30: 12 | T30: 18(0) | U30: 41 | V30: 347(0) | W30: 1 | Y30: 1G | Z30: 1G | AB30: X | AC30: 34 | AD30: =AF30 -> 0 | AE30: 33 | AF30: 0 | AG30: 7 | AH30: 0 | AI30: 33 | AJ30: 7 | AK30: 2 | AL30: 18 | AQ30: 0 | AR30: =SUM(AS30:BB30) -> 34 | AS30: 0 | AT30: 0 | AU30: 0 | AV30: 2 | AW30: 0 | AX30: 28 | AY30: 0 | AZ30: 0 | BA30: 0 | BB30: 4 | BC30: 집선스위치>>스쿨넷회선 구간 측정
B31: 260 | C31: N108161019MS | D31: S120000280 | E31: Y | F31: 충남 | G31: 공주 | H31: 중학교 | I31: 공주영명중학교 | J31: 충남 공주시 영명학당2길 33 | K31: 2480 | L31: 김은호 | M31: 정보 | N31: 김은호 | O31: 041-858-0325 | P31: nsarang95@naver.com | Q31: 4 | R31: 12(6) | S31: 6 | T31: 6(0) | U31: 16 | V31: 132(0) | W31: 1 | Y31: 80M | Z31: 80M | AB31: X | AC31: 15 | AD31: =AF31 -> 0 | AE31: 14 | AF31: 0 | AG31: 4 | AH31: 0 | AI31: 14 | AJ31: 4 | AK31: 2 | AL31: 8 | AQ31: 0 | AR31: =SUM(AS31:BB31) -> 15 | AS31: 0 | AT31: 0 | AU31: 0 | AV31: 0 | AW31: 0 | AX31: 6 | AY31: 1 | AZ31: 0 | BA31: 0 | BB31: 8 | BC31: 집선스위치>>스쿨넷회선 구간 측정
B32: 70 | C32: N108140174SS | D32: S120001249 | E32: Y | F32: 충남 | G32: 공주 | H32: 특수학교 | I32: 공주정명학교 | J32: 충남 공주시 장척로 116-14 | K32: 30763 | L32: 정택함 | M32: 정보 | N32: 정택함 | O32: 041)857-1522 | P32: xorgka04@naver.com | Q32: 5 | R32: 48(27) | S32: 10 | T32: 25(2) | U32: 51 | V32: 106(1) | W32: 1 | Y32: 1G | Z32: 1G | AB32: X | AC32: 38 | AD32: =AF32 -> 0 | AE32: 38 | AF32: 0 | AG32: 9 | AH32: 0 | AI32: 38 | AJ32: 9 | AK32: 2 | AL32: 16 | AQ32: 0 | AR32: =SUM(AS32:BB32) -> 38 | AS32: 0 | AT32: 0 | AU32: 0 | AV32: 3 | AW32: 0 | AX32: 35 | AY32: 0 | AZ32: 0 | BA32: 0 | BB32: 0 | BC32: 집선스위치>>스쿨넷회선 구간 측정
B33: 76 | C33: N108140196HS | D33: S120000138 | E33: Y | F33: 충남 | G33: 공주 | H33: 고등학교 | I33: 공주정보고등학교 | J33: 충남 공주시 마근동길 29 | K33: 28931 | L33: 지경숙 | M33: 정보 | N33: 지경숙 | O33: 041-856-1674 | P33: lovlov3737@gmail.com | Q33: 4 | R33: 16(4) | S33: 7 | T33: 12(0) | U33: 31 | V33: 182(0) | W33: 5 | Y33: 1G | Z33: 1G | AB33: X | AC33: 28 | AD33: =AF33 -> 0 | AE33: 27 | AF33: 0 | AG33: 6 | AH33: 0 | AI33: 27 | AJ33: 6 | AK33: 2 | AL33: 19 | AQ33: 0 | AR33: =SUM(AS33:BB33) -> 28 | AS33: 0 | AT33: 0 | AU33: 0 | AV33: 0 | AW33: 0 | AX33: 28 | AY33: 0 | AZ33: 0 | BA33: 0 | BB33: 0 | BC33: 집선스위치>>스쿨넷회선 구간 측정
B34: 267 | C34: N108161026ES | D34: S120000299 | E34: Y | F34: 충남 | G34: 공주 | H34: 초등학교 | I34: 공주중동초등학교 | J34: 충남 공주시 웅진로 146-5 | K34: 2482 | L34: 류지찬 | M34: 정보 | N34: 류지찬 | O34: 041-850-9693 | P34: 5327681@naver.com | Q34: 5 | R34: 26(13) | S34: 11 | T34: 10(2) | U34: 20 | V34: 130(9) | W34: 1 | Y34: 1G | Z34: 1G | AB34: X | AC34: 18 | AD34: =AF34 -> 0 | AE34: 18 | AF34: 0 | AG34: 8 | AH34: 0 | AI34: 18 | AJ34: 9 | AK34: 2 | AL34: 16 | AQ34: 0 | AR34: =SUM(AS34:BB34) -> 18 | AS34: 0 | AT34: 0 | AU34: 0 | AV34: 0 | AW34: 0 | AX34: 13 | AY34: 5 | AZ34: 0 | BA34: 0 | BB34: 0 | BC34: 집선스위치>>스쿨넷회선 구간 측정
B35: 249 | C35: N108161006MS | D35: S120000281 | E35: Y | F35: 충남 | G35: 공주 | H35: 중학교 | I35: 공주중학교 | J35: 충남 공주시 왕릉로 111 | K35: 8167 | L35: 이병만 | M35: 정보 | N35: 이병만 | O35: 041-960-3518 | P35: manicomu@naver.com | Q35: 4 | R35: 20(5) | S35: 16 | T35: 17(3) | U35: 42 | V35: 347(13) | W35: 1 | Y35: 1G | Z35: 1G | AB35: X | AC35: 37 | AD35: =AF35 -> 0 | AE35: 37 | AF35: 0 | AG35: 8 | AH35: 0 | AI35: 37 | AJ35: 8 | AK35: 2 | AL35: 25 | AQ35: 0 | AR35: =SUM(AS35:BB35) -> 37 | AS35: 0 | AT35: 0 | AU35: 0 | AV35: 0 | AW35: 0 | AX35: 21 | AY35: 3 | AZ35: 0 | BA35: 0 | BB35: 13 | BC35: 집선스위치>>스쿨넷회선 구간 측정
B36: 268 | C36: N108161027ES | D36: S120000302 | E36: Y | F36: 충남 | G36: 공주 | H36: 초등학교 | I36: 구산초등학교 | J36: 충남 공주시 유구읍 유구마곡사로 61-1 | K36: 25715 | Q36: 3 | R36: 11(5) | S36: 10 | T36: 6(0) | U36: 12 | V36: 34(0) | W36: 1 | Y36: 60M | Z36: 60M | AB36: X | AC36: 13 | AD36: =AF36 -> 0 | AE36: 13 | AF36: 0 | AG36: 2 | AH36: 0 | AI36: 13 | AJ36: 2 | AK36: 2 | AL36: 10 | AQ36: 0 | AR36: =SUM(AS36:BB36) -> 13 | AS36: 0 | AT36: 0 | AU36: 0 | AV36: 0 | AW36: 0 | AX36: 6 | AY36: 0 | AZ36: 0 | BA36: 0 | BB36: 7 | BC36: 집선스위치>>스쿨넷회선 구간 측정
B37: 760 | C37: N10C035903HS | D37: S000003496 | E37: Y | F37: 충남 | G37: 공주 | H37: 고등학교 | I37: 국립공주대학교사범대학부설고등학교 | J37: 충남 공주시 봉황로 75 | K37: 20560 | Q37: 5 | R37: 38(15) | S37: 19 | T37: 19(1) | U37: 53 | V37: 452(3) | W37: 1 | Y37: 1G | Z37: 1G | AB37: X | AC37: 0 | AD37: =AF37 -> 36 | AE37: 0 | AF37: 36 | AG37: 0 | AH37: 0 | AI37: 36 | AJ37: 0 | AK37: 2 | AL37: 25 | AO37: 5 | AP37: 부설중과 스쿨넷 회선공유 / 무선 자체AP | AQ37: 5 | AR37: =SUM(AS37:BB37) -> 0 | AS37: 0 | AT37: 0 | AU37: 0 | AV37: 0 | AW37: 0 | AX37: 0 | AY37: 0 | AZ37: 0 | BA37: 0 | BB37: 0 | BC37: 집선스위치>>스쿨넷회선 구간 측정
B38: 759 | C38: N10C035902MS | D38: S000003501 | E38: Y | F38: 충남 | G38: 공주 | H38: 중학교 | I38: 국립공주대학교사범대학부설중학교 | J38: 충남 공주시 봉황로 75 | K38: 19464 | Q38: 3 | R38: 7(1) | S38: 5 | T38: 7(1) | U38: 23 | V38: 161(6) | W38: 1 | Y38: 부설고공유 | Z38: (1G) | AB38: X | AC38: 0 | AD38: =AF38 -> 23 | AE38: 0 | AF38: 23 | AG38: 0 | AH38: 2 | AI38: 23 | AJ38: 2 | AK38: 2 | AL38: 11 | AO38: 5 | AP38: 부설고와 스쿨넷 회선공유 / 무선 자체AP | AQ38: 5 | AR38: =SUM(AS38:BB38) -> 0 | AS38: 0 | AT38: 0 | AU38: 0 | AV38: 0 | AW38: 0 | AX38: 0 | AY38: 0 | AZ38: 0 | BA38: 0 | BB38: 0 | BC38: 집선스위치>>스쿨넷회선 구간 측정
B39: 761 | C39: N10C036093SS | D39: S000006122 | E39: Y | F39: 충남 | G39: 공주 | H39: 특수학교 | I39: 국립공주대학교사범대학부설특수학교 | J39: 충남 공주시 우금티로 753 | K39: 45536 | Q39: 2 | R39: 29(11) | S39: 11 | T39: 12(0) | U39: 27 | V39: 70(0) | W39: 2 | Y39: 1G | Z39: 1G | AB39: X | AC39: 0 | AD39: =AF39 -> 69 | AE39: 0 | AF39: 69 | AG39: 0 | AH39: 7 | AI39: 42 | AJ39: 3 | AK39: 1 | AL39: 89 | AO39: 1 | AP39: 무선 자체AP | AQ39: 0 | AR39: =SUM(AS39:BB39) -> 0 | AS39: 0 | AT39: 0 | AU39: 0 | AV39: 0 | AW39: 0 | AX39: 0 | AY39: 0 | AZ39: 0 | BA39: 0 | BB39: 0 | BC39: 집선스위치>>스쿨넷회선 구간 측정
B40: 269 | C40: N108161028ES | D40: S120000304 | E40: Y | F40: 충남 | G40: 공주 | H40: 초등학교 | I40: 귀산초등학교 | J40: 충남 공주시 우성면 귀산길 81-15 | K40: 15213 | L40: 주종민 | M40: 정보 | N40: 주종민 | O40: 041-854-7301 | P40: hibes@naver.com | Q40: 4 | R40: 9(2) | S40: 4 | T40: 6(0) | U40: 12 | V40: 49(0) | W40: 1 | Y40: 60M | Z40: 60M | AB40: X | AC40: 10 | AD40: =AF40 -> 3 | AE40: 10 | AF40: 3 | AG40: 3 | AH40: 0 | AI40: 13 | AJ40: 3 | AK40: 2 | AL40: 20 | AQ40: 0 | AR40: =SUM(AS40:BB40) -> 10 | AS40: 0 | AT40: 2 | AU40: 0 | AV40: 0 | AW40: 0 | AX40: 5 | AY40: 2 | AZ40: 0 | BA40: 0 | BB40: 1 | BC40: 집선스위치>>스쿨넷회선 구간 측정
...

Sheet 0.학교(충남)
AB1: SWIMS연동 AP 수량
AB2: 제조사 | AC2: H1Radio | AE2: MERCURY | AF2: 가온브로드밴드 | AH2: 다보링크 | AK2: 엘텍 | AL2: 다산네트웍스
A3: 학교코드 | B3: 정보공시코드 | C3: 발행 | D3: 교육청 | E3: 지역 | F3: 학교유형 | G3: 학교명 | H3: 주소 | I3: 설립연도 | J3: 담당 선생님 이름 | K3: 담당 선생님 업무 | L3: 직통 연락처 | M3: 이메일 | N3: 건물수 | O3: 교실수 (특수) | P3: 교무 (연구)/ 행정실수 | Q3: 학급수 (특수) | R3: 교직원수 | S3: 학생수 | T3: 컴퓨터실 수 | U3: 망분리 여부 | V3: 스쿨넷 회선속도 | W3: 무선망 전용 회선속도 | X3: 10G 청약 여부 | Y3: SWIMS 연동 AP 수량 | Z3: 학교 자체 AP 수량 | AA3: 학교 특이사항 | AB3: 모델명 / 합계 | AC3: AR-WF6E-2564I | AD3: H1-A7114N | AE3: MCAP-704SM | AF3: EAP2244 | AG3: EAP2245 | AH3: DVW604 | AI3: DVW624 | AJ3: DVW704 | AK3: H834AX-P | AL3: W340 | AM3: 분류1 | AN3: 분류2 | AO3: 분류3
A4: N108140237HS | B4: S120002546 | C4: Y | D4: 충남 | E4: 계룡 | F4: 고등학교 | G4: 계룡고등학교 | H4: 충남 계룡시 두마면 서금암로 89 | I4: 38833 | J4: 김대성 | K4: 정보 | L4: 042-840-5314 | M4: kimds0316@naver.com | N4: 2 | O4: 27(6) | P4: 9 | Q4: 22(1) | R4: 57 | S4: 578(8) | T4: 1 | U4: 미분리 | V4: 1G | W4: N/A | X4: X | Y4: 39 | AB4: =SUM(AC4:AL4) -> 39 | AC4: 0 | AD4: 0 | AE4: 0 | AF4: 4 | AG4: 2 | AH4: 24 | AI4: 0 | AJ4: 0 | AK4: 0 | AL4: 9 | AM4: 업무/교육/기타망 미분리
A5: N108222124ES | B5: S120002976 | C5: N | D5: 충남 | E5: 계룡 | F5: 초등학교 | G5: 계룡대실초등학교 | H5: 충남 계룡시 두마면 대실남북로 113 | I5: 45717 | J5: 조창희 | K5: 정보 | L5: 042-710-4701 | M5: gomtingjo@naver.com | N5: 2 | O5: 38(7) | P5: 11 | Q5: 22(1) | R5: 32 | S5: 441(4) | T5: 1 | U5: 분리 | V5: 1G | W5: N/A | X5: X | Y5: 73 | AA5: 신설학교 | AB5: =SUM(AC5:AL5) -> 73 | AC5: 0 | AD5: 0 | AE5: 0 | AF5: 0 | AG5: 73 | AH5: 0 | AI5: 0 | AJ5: 0 | AK5: 0 | AL5: 0 | AM5: 분리
A6: N108222119MS | B6: S120002545 | C6: Y | D6: 충남 | E6: 계룡 | F6: 중학교 | G6: 계룡중학교 | H6: 충남 계룡시 서금암 5길 17 | I6: 38777 | J6: 양현원 | K6: 정보 | N6: 2 | O6: 34(6) | P6: 15 | Q6: 28(2) | R6: 59 | S6: 659(8) | T6: 1 | U6: 미분리 | V6: 60M | W6: 2.5G | X6: O | Y6: 34 | AB6: =SUM(AC6:AL6) -> 34 | AC6: 0 | AD6: 0 | AE6: 0 | AF6: 0 | AG6: 1 | AH6: 29 | AI6: 3 | AJ6: 0 | AK6: 0 | AL6: 1 | AM6: 업무/기타망 미분리
A7: N108222061ES | C7: Y | D7: 충남 | E7: 계룡 | F7: 초등학교 | G7: 금암초등학교 | H7: 충남 계룡시 장안로 104 | I7: 38777 | J7: 문숙 | K7: 정보 | L7: 042-841-0872 | M7: swani3@hanmail.net | N7: 10 | O7: 22(3) | P7: 7 | Q7: 18(1) | R7: 49 | S7: 365(10) | T7: 1 | U7: 미분리 | V7: 1G | W7: 2.5G | X7: O | Y7: 29 | AB7: =SUM(AC7:AL7) -> 29 | AC7: 0 | AD7: 4 | AE7: 0 | AF7: 0 | AG7: 4 | AH7: 2 | AI7: 15 | AJ7: 0 | AK7: 0 | AL7: 4 | AM7: 업무/교육/기타망 미분리
A8: N108222036ES | B8: S120000459 | C8: Y | D8: 충남 | E8: 계룡 | F8: 초등학교 | G8: 두마초등학교 | H8: 충남 계룡시 두마면 팥거리로 160 | I8: 8553 | L8: 010-3813-3682 | M8: topfgfl@naver.com | N8: 8 | O8: 28(5) | P8: 6 | Q8: 19(2) | R8: 31 | S8: 331(8) | T8: 1 | U8: 미분리 | V8: 1G | W8: 2.5G | X8: O | Y8: 33 | AB8: =SUM(AC8:AL8) -> 33 | AC8: 0 | AD8: 0 | AE8: 0 | AF8: 0 | AG8: 0 | AH8: 23 | AI8: 1 | AJ8: 0 | AK8: 0 | AL8: 9 | AM8: 업무/교육/기타망 미분리
A9: N108222019ES | B9: S120002529 | C9: Y | D9: 충남 | E9: 계룡 | F9: 초등학교 | G9: 신도초등학교 | H9: 충남 계룡시 엄사면 번영3길 82 | I9: 38412 | J9: 최수현 | K9: 정보 | L9: 042-841-9860 | M9: dhw1105@korea.kr | N9: 3 | O9: 31(6) | P9: 11 | Q9: 18(3) | R9: 28 | S9: 320(13) | T9: 1 | U9: 미분리 | V9: 60M | W9: 2.5G | X9: O | Y9: 29 | AB9: =SUM(AC9:AL9) -> 29 | AC9: 0 | AD9: 0 | AE9: 0 | AF9: 3 | AG9: 1 | AH9: 11 | AI9: 3 | AJ9: 0 | AK9: 0 | AL9: 11 | AM9: 업무/교육/기타망 미분리
A10: N108222017MS | B10: S120000434 | C10: Y | D10: 충남 | E10: 계룡 | F10: 중학교 | G10: 엄사중학교 | H10: 충남 계룡시 엄사면 번영11길3 | I10: 36586 | L10: 042-841-9676 | N10: 2 | O10: 26(5) | P10: 17 | Q10: 20(1) | R10: 49 | S10: 511(6) | T10: 1 | U10: 미분리 | V10: 1G | W10: 2.5G | X10: O | Y10: 41 | AB10: =SUM(AC10:AL10) -> 41 | AC10: 0 | AD10: 0 | AE10: 0 | AF10: 0 | AG10: 1 | AH10: 32 | AI10: 3 | AJ10: 0 | AK10: 0 | AL10: 5 | AM10: 업무/기타망 미분리
A11: N108222046ES | B11: S120000479 | C11: Y | D11: 충남 | E11: 계룡 | F11: 초등학교 | G11: 엄사초등학교 | H11: 충남 계룡시 엄사면 번영3길 30 | I11: 34947 | L11: 042 841 4497 | M11: xkskxhshxm57@naver.com | N11: 4 | O11: 22(5) | P11: 11 | Q11: 17(1) | R11: 25 | S11: 301(4) | T11: 1 | U11: 미분리 | V11: 1G | W11: N/A | X11: X | Y11: 30 | AB11: =SUM(AC11:AL11) -> 30 | AC11: 0 | AD11: 0 | AE11: 0 | AF11: 0 | AG11: 0 | AH11: 25 | AI11: 1 | AJ11: 0 | AK11: 0 | AL11: 4 | AM11: 업무/기타망 미분리
A12: N108140063HS | B12: S120000218 | C12: Y | D12: 충남 | E12: 계룡 | F12: 고등학교 | G12: 용남고등학교 | H12: 충남 계룡시 신도안면 신도안1길 32 | I12: 33306 | J12: 정일영 | K12: 정보 | L12: 042-717-2160 | N12: 4 | O12: 40(9) | P12: 18 | Q12: 31(1) | R12: 76 | S12: 817(6) | T12: 1 | U12: 미분리 | V12: 1G | W12: 2.5G | X12: O | Y12: 54 | AB12: =SUM(AC12:AL12) -> 54 | AC12: 0 | AD12: 0 | AE12: 0 | AF12: 4 | AG12: 4 | AH12: 46 | AI12: 0 | AJ12: 0 | AK12: 0 | AL12: 0 | AM12: 업무/기타망 미분리
A13: N108222012MS | B13: S120000439 | C13: Y | D13: 충남 | E13: 계룡 | F13: 중학교 | G13: 용남중학교 | H13: 충남 계룡시 신도안면 신도안2길 66 | I13: 32752 | J13: 이정재 | K13: 정보 | L13: 042-551-1501 | M13: pisicc00@ai.cne.go.kr | N13: 4 | O13: 29(4) | P13: 13 | Q13: 23(1) | R13: 55 | S13: 605(3) | T13: 1 | U13: 미분리 | V13: 1G | W13: 2.5G | X13: O | Y13: 35 | AB13: =SUM(AC13:AL13) -> 35 | AC13: 0 | AD13: 0 | AE13: 0 | AF13: 0 | AG13: 1 | AH13: 0 | AI13: 3 | AJ13: 0 | AK13: 0 | AL13: 31 | AM13: 업무/교육/기타망 미분리
A14: N108222051ES | C14: Y | D14: 충남 | E14: 계룡 | F14: 초등학교 | G14: 용남초등학교 | H14: 충남 계룡시 신도안면 신도안1길 88 | I14: 32758 | L14: 042-551-1504 | M14: tnwls284566@naver.com | N14: 4 | O14: 48(5) | P14: 5 | Q14: 39(1) | R14: 83 | S14: 906(4) | T14: 2 | U14: 미분리 | V14: 1G | W14: 5G | X14: O | Y14: 51 | AB14: =SUM(AC14:AL14) -> 51 | AC14: 0 | AD14: 2 | AE14: 0 | AF14: 0 | AG14: 3 | AH14: 41 | AI14: 4 | AJ14: 0 | AK14: 0 | AL14: 1 | AM14: 업무/교육/기타망 미분리
A15: N108161016MS | B15: S120000277 | C15: Y | D15: 충남 | E15: 공주 | F15: 중학교 | G15: 경천중학교 | H15: 충남 공주시 계룡면 어사길2 | I15: 25490 | J15: 조은아 | K15: 정보 | L15: 041-852-4043 | M15: jea168@naver.com | N15: 2 | O15: 8(5) | P15: 3 | Q15: 3(0) | R15: 9 | S15: 32(0) | T15: 1 | U15: 미분리 | V15: 60M | W15: N/A | X15: X | Y15: 8 | AB15: =SUM(AC15:AL15) -> 8 | AC15: 0 | AD15: 2 | AE15: 0 | AF15: 0 | AG15: 0 | AH15: 4 | AI15: 2 | AJ15: 0 | AK15: 0 | AL15: 0 | AM15: 업무/교육/기타망 미분리
A16: N108161021ES | B16: S120000293 | C16: Y | D16: 충남 | E16: 공주 | F16: 초등학교 | G16: 경천초등학교 | H16: 충남 공주시 계룡면 신원사로112 | I16: 16577 | J16: 김채원 | K16: 정보 | L16: 010-6402-3568 | M16: 1234567na@naver.com | N16: 2 | O16: 9(3) | P16: 5 | Q16: 6(0) | R16: 11 | S16: 14(0) | U16: 미분리 | V16: 60M | W16: N/A | X16: X | Y16: 12 | AB16: =SUM(AC16:AL16) -> 12 | AC16: 0 | AD16: 0 | AE16: 0 | AF16: 0 | AG16: 0 | AH16: 0 | AI16: 8 | AJ16: 0 | AK16: 0 | AL16: 4 | AM16: 업무/교육/기타망 미분리
A17: N108161022ES | B17: S120000294 | C17: Y | D17: 충남 | E17: 공주 | F17: 초등학교 | G17: 계룡초등학교 | H17: 충남 공주시 계룡면 영규대사로 459 | I17: 7108 | L17: 041-857-5023 | M17: dbfla802@naver.com | N17: 3 | O17: 11(5) | P17: 6 | Q17: 6(0) | R17: 18 | S17: 40(0) | T17: 2 | U17: 미분리 | V17: 60M | W17: N/A | X17: X | Y17: 10 | AB17: =SUM(AC17:AL17) -> 10 | AC17: 0 | AD17: 0 | AE17: 0 | AF17: 0 | AG17: 0 | AH17: 8 | AI17: 1 | AJ17: 0 | AK17: 0 | AL17: 1 | AM17: 업무/기타망 미분리
A18: N108140036HS | B18: S120000131 | C18: Y | D18: 충남 | E18: 공주 | F18: 고등학교 | G18: 공주고등학교 | H18: 충남 공주시 공주고담길 2 | I18: 8167 | L18: 041-855-1705 | M18: phlox898@gmail.com | N18: 7 | O18: 41(14) | P18: 22 | Q18: 25(1) | R18: 65 | S18: 491(4) | T18: 1 | U18: 미분리 | V18: 1G | W18: N/A | X18: X | Y18: 53 | AB18: =SUM(AC18:AL18) -> 53 | AC18: 0 | AD18: 0 | AE18: 0 | AF18: 1 | AG18: 0 | AH18: 30 | AI18: 9 | AJ18: 0 | AK18: 0 | AL18: 13 | AM18: 업무/교육/기타망 미분리
A19: N108161023ES | B19: S120000295 | C19: Y | D19: 충남 | E19: 공주 | F19: 초등학교 | G19: 공주교동초등학교 | H19: 충남 공주시 용당길 69-6 | I19: 24523 | J19: 윤송원 | K19: 정보 | L19: 010-8651-2480 | M19: hobbang305@naver.com | N19: 2 | O19: 10(1) | P19: 6 | Q19: 8(1) | R19: 15 | S19: 120(5) | T19: 1 | U19: 미분리 | V19: 1G | W19: N/A | X19: X | Y19: 31 | AB19: =SUM(AC19:AL19) -> 31 | AC19: 0 | AD19: 9 | AE19: 0 | AF19: 0 | AG19: 0 | AH19: 21 | AI19: 1 | AJ19: 0 | AK19: 0 | AL19: 0 | AM19: 업무/교육/기타망 미분리
A20: N107004442ES | B20: S000003499 | C20: Y | D20: 충남 | E20: 공주 | F20: 초등학교 | G20: 공주교육대학교부설초등학교 | H20: 충남 공주시 하선길 47 | I20: 13993 | N20: 4 | O20: 36(11) | P20: 7 | Q20: 25(1) | R20: 33 | S20: 469(6) | U20: 확인불가 | V20: 1G | W20: N/A | X20: X | Y20: 0 | AB20: =SUM(AC20:AL20) -> 0 | AC20: 0 | AD20: 0 | AE20: 0 | AF20: 0 | AG20: 0 | AH20: 0 | AI20: 0 | AJ20: 0 | AK20: 0 | AL20: 0 | AM20: 확인불가
A21: N108140080HS | B21: S120000133 | C21: Y | D21: 충남 | E21: 공주 | F21: 고등학교 | G21: 공주금성여자고등학교 | H21: 충남 공주시 무령로 103 | I21: 29285 | J21: 김동규 | K21: 정보 | L21: 041-8546811 | M21: dongkyu7530@naver.com | N21: 5 | O21: 31(10) | P21: 27 | Q21: 21(0) | R21: 44 | S21: 390(0) | T21: 1 | U21: 미분리 | V21: 1G | W21: N/A | X21: X | Y21: 36 | AB21: =SUM(AC21:AL21) -> 36 | AC21: 0 | AD21: 0 | AE21: 0 | AF21: 0 | AG21: 0 | AH21: 27 | AI21: 0 | AJ21: 0 | AK21: 0 | AL21: 9 | AM21: 업무/교육/기타망 미분리
A22: N108161024ES | B22: S120000296 | C22: Y | D22: 충남 | E22: 공주 | F22: 초등학교 | G22: 공주금학초등학교 | H22: 충남 공주시 공주고담길 19 | I22: 14758 | N22: 3 | O22: 9(2) | P22: 8 | Q22: 7(1) | R22: 12 | S22: 47(4) | T22: 1 | U22: 미분리 | V22: 60M | W22: N/A | X22: X | Y22: 13 | AB22: =SUM(AC22:AL22) -> 13 | AC22: 0 | AD22: 0 | AE22: 0 | AF22: 0 | AG22: 0 | AH22: 6 | AI22: 0 | AJ22: 0 | AK22: 0 | AL22: 7 | AM22: 업무/교육/기타망 미분리
A23: N108140347HS | B23: S120000132 | C23: Y | D23: 충남 | E23: 공주 | F23: 고등학교 | G23: 공주마이스터고등학교 | H23: 충남 공주시 유구읍 중앙1길 27-12 | I23: 26372 | J23: 박진수 | K23: 정보 | L23: 041-840-1441 | M23: pjs8674@naver.com | N23: 5 | O23: 35(22) | P23: 12 | Q23: 13(1) | R23: 38 | S23: 190(2) | U23: 미분리 | V23: 1G | W23: N/A | X23: X | Y23: 42 | AB23: =SUM(AC23:AL23) -> 42 | AC23: 0 | AD23: 0 | AE23: 0 | AF23: 3 | AG23: 0 | AH23: 17 | AI23: 8 | AJ23: 0 | AK23: 0 | AL23: 14 | AM23: 업무/교육/기타망 미분리
A24: N108161025ES | B24: S120000297 | C24: Y | D24: 충남 | E24: 공주 | F24: 초등학교 | G24: 공주봉황초등학교 | H24: 충남 공주시 오거리길5 | I24: 16735 | J24: 황순기 | K24: 정보 | L24: 041-854-2203 | M24: skee0079@naver.com | N24: 3 | O24: 12(5) | P24: 6 | Q24: 7(1) | R24: 12 | S24: 73(4) | T24: 1 | U24: 미분리 | V24: 60M | W24: N/A | X24: X | Y24: 10 | AB24: =SUM(AC24:AL24) -> 10 | AC24: 0 | AD24: 0 | AE24: 0 | AF24: 0 | AG24: 0 | AH24: 2 | AI24: 7 | AJ24: 0 | AK24: 0 | AL24: 1 | AM24: 업무/교육/기타망 미분리
A25: N108161017MS | B25: S120000278 | C25: Y | D25: 충남 | E25: 공주 | F25: 중학교 | G25: 공주북중학교 | H25: 충남 공주시 제민천1길 113 | I25: 24819 | L25: 041-854-3962 | M25: artman7@hanmail.net | N25: 3 | O25: 12(3) | P25: 7 | Q25: 9(0) | R25: 19 | S25: 214(0) | T25: 1 | U25: 미분리 | V25: 1G | W25: N/A | X25: X | Y25: 16 | AB25: =SUM(AC25:AL25) -> 16 | AC25: 0 | AD25: 12 | AE25: 0 | AF25: 0 | AG25: 0 | AH25: 0 | AI25: 4 | AJ25: 0 | AK25: 0 | AL25: 0 | AM25: 업무/기타망 미분리
A26: N108140238HS | B26: S120000134 | C26: Y | D26: 충남 | E26: 공주 | F26: 고등학교 | G26: 공주생명과학고등학교 | H26: 충남 공주시 금벽로 317 | I26: 12126 | J26: 송민주 | K26: 정보 | L26: 041-858-3500(3503~6) | M26: belle0037@naver.com | N26: 18 | O26: 56(25) | P26: 9 | Q26: 18(3) | R26: 45 | S26: 259(18) | T26: 2 | U26: 미분리 | V26: 1G | W26: N/A | X26: X | Y26: 55 | AB26: =SUM(AC26:AL26) -> 55 | AC26: 0 | AD26: 0 | AE26: 0 | AF26: 1 | AG26: 0 | AH26: 54 | AI26: 0 | AJ26: 0 | AK26: 0 | AL26: 0 | AM26: 업무/교육/기타망 미분리
A27: N108161020ES | B27: S120000298 | C27: Y | D27: 충남 | E27: 공주 | F27: 초등학교 | G27: 공주신월초등학교 | H27: 충남 공주시 번영1로 193 | I27: 37408 | L27: 0418815013 | M27: tlstnans@cne.go.kr | N27: 3 | O27: 52(8) | P27: 3 | Q27: 45(2) | R27: 72 | S27: 1075(10) | T27: 2 | U27: 미분리 | V27: 1G | W27: 5G | X27: O | Y27: 59 | AB27: =SUM(AC27:AL27) -> 59 | AC27: 0 | AD27: 0 | AE27: 0 | AF27: 0 | AG27: 0 | AH27: 46 | AI27: 5 | AJ27: 0 | AK27: 0 | AL27: 8 | AM27: 업무/기타망 미분리
A28: N108140037HS | B28: S120000135 | C28: Y | D28: 충남 | E28: 공주 | F28: 고등학교 | G28: 공주여자고등학교 | H28: 충남 공주시 공주여고길 14-1 | I28: 10349 | N28: 5 | O28: 40(18) | P28: 13 | Q28: 22(1) | R28: 56 | S28: 407(5) | T28: 1 | U28: 미분리 | V28: 1G | W28: N/A | X28: X | Y28: 35 | AB28: =SUM(AC28:AL28) -> 35 | AC28: 0 | AD28: 0 | AE28: 0 | AF28: 0 | AG28: 0 | AH28: 28 | AI28: 2 | AJ28: 0 | AK28: 0 | AL28: 5 | AM28: 업무/교육/기타망 미분리
A29: N108161005MS | B29: S120000279 | C29: Y | D29: 충남 | E29: 공주 | F29: 중학교 | G29: 공주여자중학교 | H29: 충남 공주시 용당길 54 | I29: 10349 | J29: 민선주 | K29: 정보 | L29: 041-851-1001 | M29: miracle@ai.cne.go.kr | N29: 3 | O29: 28(10) | P29: 13 | Q29: 22(1) | R29: 51 | S29: 549(3) | T29: 1 | U29: 미분리 | V29: 1G | W29: 2.5G | X29: O | Y29: 35 | AB29: =SUM(AC29:AL29) -> 35 | AC29: 0 | AD29: 0 | AE29: 0 | AF29: 0 | AG29: 0 | AH29: 22 | AI29: 4 | AJ29: 0 | AK29: 0 | AL29: 9 | AM29: 업무/기타망 미분리
A30: N108140082HS | B30: S120000137 | C30: Y | D30: 충남 | E30: 공주 | F30: 고등학교 | G30: 공주영명고등학교 | H30: 충남 공주시 중동 영명학당2길 33 | I30: 2480 | J30: 홍록기 | K30: 정보 | L30: 041-854-3382 | M30: lokki@hanmail.net | N30: 5 | O30: 37(13) | P30: 12 | Q30: 18(0) | R30: 41 | S30: 347(0) | T30: 1 | U30: 확인불가 | V30: 1G | W30: N/A | X30: X | Y30: 34 | AB30: =SUM(AC30:AL30) -> 34 | AC30: 0 | AD30: 0 | AE30: 0 | AF30: 2 | AG30: 0 | AH30: 28 | AI30: 0 | AJ30: 0 | AK30: 0 | AL30: 4 | AM30: 확인불가
A31: N108161019MS | B31: S120000280 | C31: Y | D31: 충남 | E31: 공주 | F31: 중학교 | G31: 공주영명중학교 | H31: 충남 공주시 영명학당2길 33 | I31: 2480 | J31: 김은호 | K31: 정보 | L31: 041-858-0325 | M31: nsarang95@naver.com | N31: 4 | O31: 12(6) | P31: 6 | Q31: 6(0) | R31: 16 | S31: 132(0) | T31: 1 | U31: 미분리 | V31: 80M | W31: N/A | X31: X | Y31: 15 | AB31: =SUM(AC31:AL31) -> 15 | AC31: 0 | AD31: 0 | AE31: 0 | AF31: 0 | AG31: 0 | AH31: 6 | AI31: 1 | AJ31: 0 | AK31: 0 | AL31: 8 | AM31: 업무/교육/기타망 미분리
A32: N108140174SS | B32: S120001249 | C32: Y | D32: 충남 | E32: 공주 | F32: 특수학교 | G32: 공주정명학교 | H32: 충남 공주시 장척로 116-14 | I32: 30763 | J32: 정택함 | K32: 정보 | L32: 041)857-1522 | M32: xorgka04@naver.com | N32: 5 | O32: 48(27) | P32: 10 | Q32: 25(2) | R32: 51 | S32: 106(1) | T32: 1 | U32: 미분리 | V32: 1G | W32: N/A | X32: X | Y32: 38 | AB32: =SUM(AC32:AL32) -> 38 | AC32: 0 | AD32: 0 | AE32: 0 | AF32: 3 | AG32: 0 | AH32: 35 | AI32: 0 | AJ32: 0 | AK32: 0 | AL32: 0 | AM32: 업무/교육/기타망 미분리
A33: N108140196HS | B33: S120000138 | C33: Y | D33: 충남 | E33: 공주 | F33: 고등학교 | G33: 공주정보고등학교 | H33: 충남 공주시 마근동길 29 | I33: 28931 | J33: 지경숙 | K33: 정보 | L33: 041-856-1674 | M33: lovlov3737@gmail.com | N33: 4 | O33: 16(4) | P33: 7 | Q33: 12(0) | R33: 31 | S33: 182(0) | T33: 5 | U33: 미분리 | V33: 1G | W33: N/A | X33: X | Y33: 28 | AB33: =SUM(AC33:AL33) -> 28 | AC33: 0 | AD33: 0 | AE33: 0 | AF33: 0 | AG33: 0 | AH33: 28 | AI33: 0 | AJ33: 0 | AK33: 0 | AL33: 0 | AM33: 업무/교육/기타망 미분리
A34: N108161026ES | B34: S120000299 | C34: Y | D34: 충남 | E34: 공주 | F34: 초등학교 | G34: 공주중동초등학교 | H34: 충남 공주시 웅진로 146-5 | I34: 2482 | J34: 류지찬 | K34: 정보 | L34: 041-850-9693 | M34: 5327681@naver.com | N34: 5 | O34: 26(13) | P34: 11 | Q34: 10(2) | R34: 20 | S34: 130(9) | T34: 1 | U34: 미분리 | V34: 1G | W34: N/A | X34: X | Y34: 18 | AB34: =SUM(AC34:AL34) -> 18 | AC34: 0 | AD34: 0 | AE34: 0 | AF34: 0 | AG34: 0 | AH34: 13 | AI34: 5 | AJ34: 0 | AK34: 0 | AL34: 0 | AM34: 업무/교육/기타망 미분리
A35: N108161006MS | B35: S120000281 | C35: Y | D35: 충남 | E35: 공주 | F35: 중학교 | G35: 공주중학교 | H35: 충남 공주시 왕릉로 111 | I35: 8167 | J35: 이병만 | K35: 정보 | L35: 041-960-3518 | M35: manicomu@naver.com | N35: 4 | O35: 20(5) | P35: 16 | Q35: 17(3) | R35: 42 | S35: 347(13) | T35: 1 | U35: 미분리 | V35: 1G | W35: N/A | X35: X | Y35: 37 | AB35: =SUM(AC35:AL35) -> 37 | AC35: 0 | AD35: 0 | AE35: 0 | AF35: 0 | AG35: 0 | AH35: 21 | AI35: 3 | AJ35: 0 | AK35: 0 | AL35: 13 | AM35: 업무/교육/기타망 미분리
A36: N108161027ES | B36: S120000302 | C36: Y | D36: 충남 | E36: 공주 | F36: 초등학교 | G36: 구산초등학교 | H36: 충남 공주시 유구읍 유구마곡사로 61-1 | I36: 25715 | N36: 3 | O36: 11(5) | P36: 10 | Q36: 6(0) | R36: 12 | S36: 34(0) | T36: 1 | U36: 미분리 | V36: 60M | W36: N/A | X36: X | Y36: 13 | AB36: =SUM(AC36:AL36) -> 13 | AC36: 0 | AD36: 0 | AE36: 0 | AF36: 0 | AG36: 0 | AH36: 6 | AI36: 0 | AJ36: 0 | AK36: 0 | AL36: 7 | AM36: 업무/교육/기타망 미분리
A37: N10C035903HS | B37: S000003496 | C37: Y | D37: 충남 | E37: 공주 | F37: 고등학교 | G37: 국립공주대학교사범대학부설고등학교 | H37: 충남 공주시 봉황로 75 | I37: 20560 | N37: 5 | O37: 38(15) | P37: 19 | Q37: 19(1) | R37: 53 | S37: 452(3) | T37: 1 | U37: 미분리 | V37: 1G | W37: N/A | X37: X | Y37: 0 | AA37: 부설중과 스쿨넷 회선공유 | AB37: =SUM(AC37:AL37) -> 0 | AC37: 0 | AD37: 0 | AE37: 0 | AF37: 0 | AG37: 0 | AH37: 0 | AI37: 0 | AJ37: 0 | AK37: 0 | AL37: 0 | AM37: 업무/교육/기타망 미분리
A38: N10C035902MS | B38: S000003501 | C38: Y | D38: 충남 | E38: 공주 | F38: 중학교 | G38: 국립공주대학교사범대학부설중학교 | H38: 충남 공주시 봉황로 75 | I38: 19464 | N38: 3 | O38: 7(1) | P38: 5 | Q38: 7(1) | R38: 23 | S38: 161(6) | T38: 1 | U38: 미분리 | V38: 부설고공유 | W38: N/A | X38: X | Y38: 0 | AA38: 부설고와 스쿨넷 회선공유 | AB38: =SUM(AC38:AL38) -> 0 | AC38: 0 | AD38: 0 | AE38: 0 | AF38: 0 | AG38: 0 | AH38: 0 | AI38: 0 | AJ38: 0 | AK38: 0 | AL38: 0 | AM38: 업무/교육/기타망 미분리
A39: N10C036093SS | B39: S000006122 | C39: Y | D39: 충남 | E39: 공주 | F39: 특수학교 | G39: 국립공주대학교사범대학부설특수학교 | H39: 충남 공주시 우금티로 753 | I39: 45536 | N39: 2 | O39: 29(11) | P39: 11 | Q39: 12(0) | R39: 27 | S39: 70(0) | T39: 2 | U39: 미분리 | V39: 1G | W39: N/A | X39: X | Y39: 0 | AB39: =SUM(AC39:AL39) -> 0 | AC39: 0 | AD39: 0 | AE39: 0 | AF39: 0 | AG39: 0 | AH39: 0 | AI39: 0 | AJ39: 0 | AK39: 0 | AL39: 0 | AM39: 업무/교육/기타망 미분리
A40: N108161028ES | B40: S120000304 | C40: Y | D40: 충남 | E40: 공주 | F40: 초등학교 | G40: 귀산초등학교 | H40: 충남 공주시 우성면 귀산길 81-15 | I40: 15213 | J40: 주종민 | K40: 정보 | L40: 041-854-7301 | M40: hibes@naver.com | N40: 4 | O40: 9(2) | P40: 4 | Q40: 6(0) | R40: 12 | S40: 49(0) | T40: 1 | U40: 미분리 | V40: 60M | W40: N/A | X40: X | Y40: 10 | AB40: =SUM(AC40:AL40) -> 10 | AC40: 0 | AD40: 2 | AE40: 0 | AF40: 0 | AG40: 0 | AH40: 5 | AI40: 2 | AJ40: 0 | AK40: 0 | AL40: 1 | AM40: 업무/교육/기타망 미분리
...

Sheet 충남(값)
I1: =COUNTIF(I5:I723, "*M")+COUNTIF(I5:I723, "*G")+COUNTIF(I5:I723, "*공유") -> 719 | J1: =COUNTIF(J5:J723, "2.5G*") -> 192 | K1: =COUNTIF(K5:K723, "확*") + COUNTIF(K5:K723, "미*") -> 704 | L1: =SUBTOTAL(102,L$5:L$723) -> 719 | M1: =COUNTIF(M5:M723, ">=1") -> 718 | N1: =COUNTIF(N5:N723, ">=1") -> 718 | O1: =COUNTIF(O5:O723, ">=1") -> 708 | P1: =COUNTIF(P5:P723, ">=1") -> 389 | Q1: =COUNTIF(Q5:Q723, ">=1") -> 421 | R1: =COUNTIF(R5:R723, ">=1") -> 412 | S1: =COUNTIF(S5:S723, ">=1") -> 106 | T1: =COUNTIF(T5:T723, ">=1") -> 32 | ... AT1: =COUNTIF(AT5:AT723, ">=1") -> 105 | AV1: =COUNTIF(AV5:AV723, ">=1") -> 587 | AW1: =COUNTIF(AW5:AW723, ">=1") -> 695 | AX1: =COUNTIF(AX5:AX723, ">=1") -> 653 | AY1: =COUNTIF(AY5:AY723, ">=1") -> 719 | AZ1: =COUNTIF(AZ5:AZ723, ">=1") -> 6 | BB1: =COUNTIF(BB5:BB723, ">=1") -> 0 | BC1: =COUNTIF(BC5:BC723, ">=1") -> 25 | BD1: =COUNTIF(BD5:BD723, ">=1") -> 25 | BE1: =COUNTIF(BE5:BE723, ">=1") -> 21 | BI1: =COUNTIF(BI5:BI723, ">=1") -> 687 | BJ1: =COUNTIF(BJ5:BJ723, ">=1") -> 25 | BK1: =COUNTIF(BK5:BK723, ">=1") -> 9 | BL1: =COUNTIF(BL5:BL723, ">=1") -> 9 | BM1: =COUNTIF(BM5:BM723, ">=1") -> 2 | BO1: =COUNTIF(BO5:BO723,">3") -> 236 | BP1: =COUNTIF(BP5:BP723, ">=1") -> 686 | BQ1: =COUNTIF(BQ5:BQ723, ">=1") -> 25 | BR1: =COUNTIF(BR5:BR723, ">=1") -> 10 | BS1: =COUNTIF(BS5:BS723, ">=1") -> 10 | BT1: =COUNTIF(BT5:BT723, ">=1") -> 1 | BV1: =COUNTIF(BV5:BV723, "=1") -> 25 | BW1: =COUNTIF(BW5:BW723, ">=1") -> 25 | BX1: =COUNTIF(BX5:BX723, ">=1") -> 24 | BY1: =COUNTIF(BY5:BY723, ">=1") -> 24 | CB1: =COUNTA(CB5:CB724) -> 15 | CC1: =COUNTA(CC5:CC724) -> 15 | CE1: =COUNTA(CE5:CE724) -> 1 | CF1: =COUNTA(CF5:CF724) -> 19
I2: =SUBTOTAL(103,I$5:I$723) -> 719 | J2: =SUBTOTAL(103,J$5:J$723) -> 192 | K2: =SUBTOTAL(103,K$5:K$723) -> 719 | L2: =SUBTOTAL(109,L$5:L$723) -> 1593 | M2: =SUBTOTAL(109,M$5:M$723) -> 718 | N2: =SUBTOTAL(109,N$5:N$723) -> 718 | O2: =SUBTOTAL(109,O$5:O$723) -> 9365 | P2: =SUBTOTAL(109,P$5:P$723) -> 1859 | Q2: =SUBTOTAL(109,Q$5:Q$723) -> 925 | R2: =SUBTOTAL(109,R$5:R$723) -> 1774 | S2: =SUBTOTAL(109,S$5:S$723) -> 196 | ... AT2: =SUBTOTAL(109,AT$5:AT$723) -> 1231 | AV2: =SUBTOTAL(109,AV$5:AV$723) -> 1610 | AW2: =SUBTOTAL(109,AW$5:AW$723) -> 4089 | AX2: =SUBTOTAL(109,AX$5:AX$723) -> 18062 | AY2: =SUBTOTAL(109,AY$5:AY$723) -> 1837 | AZ2: =SUBTOTAL(109,AZ$5:AZ$723) -> 17 | BB2: =SUBTOTAL(109,BB$5:BB$723) -> 0 | BC2: =SUBTOTAL(109,BC$5:BC$723) -> 297 | BD2: =SUBTOTAL(109,BD$5:BD$723) -> 173 | BE2: =SUBTOTAL(109,BE$5:BE$723) -> 105 | BI2: =SUBTOTAL(109,BI$5:BI$723) -> 17926 | BJ2: =SUBTOTAL(109,BJ$5:BJ$723) -> 824 | BK2: =SUBTOTAL(109,BK$5:BK$723) -> 37 | BL2: =SUBTOTAL(109,BL$5:BL$723) -> 37 | BM2: =SUBTOTAL(109,BM$5:BM$723) -> 14 | BO2: =AVERAGE(BO5:BO723) -> 2.5091427 | BP2: =SUBTOTAL(109,BP$5:BP$723) -> 17924 | BQ2: =SUBTOTAL(109,BQ$5:BQ$723) -> 826 | BR2: =SUBTOTAL(109,BR$5:BR$723) -> 54 | BS2: =SUBTOTAL(109,BS$5:BS$723) -> 54 | BT2: =SUBTOTAL(109,BT$5:BT$723) -> 1 | BV2: =COUNTIF(BV5:BV723, "=2") -> 0 | BW2: =SUBTOTAL(109,BW$5:BW$723) -> 31 | BX2: =SUBTOTAL(109,BX$5:BX$723) -> 118 | BY2: =SUBTOTAL(109,BY$5:BY$723) -> 125
